Module,Test,Test status,Error/Failure Type,Error/Failure Message
s3tests.functional.test_headers,test_object_create_date_and_amz_date,PASSED,
s3tests.functional.test_headers,test_object_create_bad_authorization_none,PASSED,
s3tests.functional.test_headers,test_bucket_create_contentlength_none,PASSED,
s3tests.functional.test_headers,test_object_acl_create_contentlength_none,PASSED,
s3tests.functional.test_headers,test_bucket_create_bad_contentlength_empty,FAILED,exceptions.AssertionError,'bad content-length' != 'bad request'
s3tests.functional.test_headers,test_bucket_create_bad_contentlength_none,PASSED,
s3tests.functional.test_headers,test_bucket_create_bad_authorization_empty,PASSED,
s3tests.functional.test_headers,test_bucket_create_bad_authorization_none,PASSED,
s3tests.functional.test_headers,test_object_create_bad_contentlength_mismatch_below_aws2,PASSED,
s3tests.functional.test_headers,test_object_create_bad_authorization_incorrect_aws2,PASSED,
s3tests.functional.test_headers,test_object_create_bad_authorization_invalid_aws2,PASSED,
s3tests.functional.test_headers,test_object_create_bad_date_none_aws2,PASSED,
s3tests.functional.test_headers,test_bucket_create_bad_authorization_invalid_aws2,PASSED,
s3tests.functional.test_headers,test_bucket_create_bad_date_none_aws2,PASSED,
s3tests.functional.test_s3,test_bucket_create_naming_bad_punctuation,PASSED,
s3tests.functional.test_s3,test_versioning_obj_read_not_exist_null,PASSED,
s3tests.functional.test_s3,test_append_object,FAILED,exceptions.AssertionError,404 != 200
s3tests.functional.test_s3,test_append_normal_object,FAILED,exceptions.AssertionError,404 != 409
s3tests.functional.test_s3,test_append_object_position_wrong,FAILED,exceptions.AssertionError,200 != 409
s3tests.functional.test_s3,test_logging_toggle,ERROR,socket.timeout,timed out
s3tests.functional.test_s3,test_atomic_write_bucket_gone,ERROR,socket.timeout,timed out
s3tests.functional.test_s3,test_encryption_sse_c_multipart_invalid_chunks_1,FAILED,exceptions.AssertionError,403 != 400
s3tests.functional.test_s3,test_encryption_sse_c_multipart_invalid_chunks_2,FAILED,exceptions.AssertionError,403 != 400
s3tests.functional.test_s3,test_bucket_policy_different_tenant,ERROR,socket.timeout,timed out
s3tests.functional.test_s3,test_bucket_policy_set_condition_operator_end_with_IfExists,ERROR,boto.exception.S3ResponseError,S3ResponseError: 400 Bad Request
s3tests.functional.test_s3,test_bucket_policy_put_obj_enc,ERROR,boto.exception.S3ResponseError,S3ResponseError: 400 Bad Request
s3tests.functional.test_s3,test_bucket_policy_put_obj_request_obj_tag,ERROR,socket.timeout,timed out
s3tests.functional.test_s3_website,check_can_test_website,ERROR,socket.timeout,timed out
s3tests.fuzz.test.test_fuzzer,test_descend_leaf_node,PASSED,
s3tests.fuzz.test.test_fuzzer,test_descend_node,PASSED,
s3tests.fuzz.test.test_fuzzer,test_descend_bad_node,PASSED,
s3tests.fuzz.test.test_fuzzer,test_descend_nonexistant_child,PASSED,
s3tests.fuzz.test.test_fuzzer,test_expand_random_printable,PASSED,
s3tests.fuzz.test.test_fuzzer,test_expand_random_binary,PASSED,
s3tests.fuzz.test.test_fuzzer,test_expand_random_printable_no_whitespace,PASSED,
s3tests.fuzz.test.test_fuzzer,test_expand_random_binary_no_whitespace,PASSED,
s3tests.fuzz.test.test_fuzzer,test_expand_random_no_args,PASSED,
s3tests.fuzz.test.test_fuzzer,test_expand_random_no_charset,PASSED,
s3tests.fuzz.test.test_fuzzer,test_expand_random_exact_length,PASSED,
s3tests.fuzz.test.test_fuzzer,test_expand_random_bad_charset,PASSED,
s3tests.fuzz.test.test_fuzzer,test_expand_random_missing_length,PASSED,
s3tests.fuzz.test.test_fuzzer,test_assemble_decision,PASSED,
s3tests.fuzz.test.test_fuzzer,test_expand_escape,PASSED,
s3tests.fuzz.test.test_fuzzer,test_expand_indirect,PASSED,
s3tests.fuzz.test.test_fuzzer,test_expand_indirect_double,PASSED,
s3tests.fuzz.test.test_fuzzer,test_expand_recursive,PASSED,
s3tests.fuzz.test.test_fuzzer,test_expand_recursive_mutual,PASSED,
s3tests.fuzz.test.test_fuzzer,test_expand_recursive_not_too_eager,PASSED,
s3tests.fuzz.test.test_fuzzer,test_make_choice_unweighted_with_space,PASSED,
s3tests.fuzz.test.test_fuzzer,test_weighted_choices,PASSED,
s3tests.fuzz.test.test_fuzzer,test_null_choices,PASSED,
s3tests.fuzz.test.test_fuzzer,test_weighted_null_choices,PASSED,
s3tests.fuzz.test.test_fuzzer,test_null_child,PASSED,
s3tests.fuzz.test.test_fuzzer,test_weighted_set,PASSED,
s3tests.fuzz.test.test_fuzzer,test_header_presence,PASSED,
s3tests.fuzz.test.test_fuzzer,test_duplicate_header,PASSED,
s3tests.fuzz.test.test_fuzzer,test_expand_headers,PASSED,
test_realistic.TestFileValidator,test_new_file_is_valid,PASSED,
test_realistic.TestFileValidator,test_new_file_is_valid_on_several_calls,PASSED,
test_realistic.TestFileValidator,test_new_file_is_valid_when_size_is_1,PASSED,
test_realistic.TestFiles,test_random_file_valid,PASSED,
s3tests_boto3.functional.test_headers,test_object_create_bad_md5_invalid_short,ERROR,botocore.errorfactory.BucketAlreadyExists,An error occurred (BucketAlreadyExists) when calling the CreateBucket operation: A vault with the provided name already exists
s3tests_boto3.functional.test_headers,test_object_create_bad_md5_bad,ERROR,botocore.errorfactory.BucketAlreadyExists,An error occurred (BucketAlreadyExists) when calling the CreateBucket operation: A vault with the provided name already exists
s3tests_boto3.functional.test_headers,test_object_create_bad_md5_empty,ERROR,botocore.errorfactory.BucketAlreadyExists,An error occurred (BucketAlreadyExists) when calling the CreateBucket operation: A vault with the provided name already exists
s3tests_boto3.functional.test_headers,test_object_create_bad_md5_none,ERROR,botocore.errorfactory.BucketAlreadyOwnedByYou,An error occurred (BucketAlreadyOwnedByYou) when calling the CreateBucket operation: Your previous request to create the named bucket succeeded and you already own it.
s3tests_boto3.functional.test_headers,test_object_create_bad_expect_mismatch,ERROR,botocore.errorfactory.BucketAlreadyOwnedByYou,An error occurred (BucketAlreadyOwnedByYou) when calling the CreateBucket operation: Your previous request to create the named bucket succeeded and you already own it.
s3tests_boto3.functional.test_headers,test_object_create_bad_expect_empty,ERROR,botocore.errorfactory.BucketAlreadyExists,An error occurred (BucketAlreadyExists) when calling the CreateBucket operation: A vault with the provided name already exists
s3tests_boto3.functional.test_headers,test_object_create_bad_expect_none,ERROR,botocore.errorfactory.BucketAlreadyExists,An error occurred (BucketAlreadyExists) when calling the CreateBucket operation: A vault with the provided name already exists
s3tests_boto3.functional.test_headers,test_object_create_bad_contentlength_empty,ERROR,botocore.errorfactory.BucketAlreadyOwnedByYou,An error occurred (BucketAlreadyOwnedByYou) when calling the CreateBucket operation: Your previous request to create the named bucket succeeded and you already own it.
s3tests_boto3.functional.test_headers,test_object_create_bad_contentlength_negative,PASSED,
s3tests_boto3.functional.test_headers,test_object_create_bad_contentlength_none,FAILED,exceptions.AssertionError,ClientError not raised
s3tests_boto3.functional.test_headers,test_object_create_bad_contentlength_mismatch_above,ERROR,botocore.errorfactory.BucketAlreadyOwnedByYou,An error occurred (BucketAlreadyOwnedByYou) when calling the CreateBucket operation: Your previous request to create the named bucket succeeded and you already own it.
s3tests_boto3.functional.test_headers,test_object_create_bad_contenttype_invalid,ERROR,botocore.errorfactory.BucketAlreadyExists,An error occurred (BucketAlreadyExists) when calling the CreateBucket operation: A vault with the provided name already exists
s3tests_boto3.functional.test_headers,test_object_create_bad_contenttype_empty,ERROR,botocore.errorfactory.BucketAlreadyOwnedByYou,An error occurred (BucketAlreadyOwnedByYou) when calling the CreateBucket operation: Your previous request to create the named bucket succeeded and you already own it.
s3tests_boto3.functional.test_headers,test_object_create_bad_contenttype_none,ERROR,botocore.errorfactory.NoSuchKey,An error occurred (NoSuchKey) when calling the PutObject operation: The specified key does not exist.
s3tests_boto3.functional.test_headers,test_object_create_bad_authorization_empty,ERROR,botocore.errorfactory.BucketAlreadyExists,An error occurred (BucketAlreadyExists) when calling the CreateBucket operation: A vault with the provided name already exists
s3tests_boto3.functional.test_headers,test_object_create_date_and_amz_date,ERROR,botocore.errorfactory.BucketAlreadyExists,An error occurred (BucketAlreadyExists) when calling the CreateBucket operation: A vault with the provided name already exists
s3tests_boto3.functional.test_headers,test_object_create_amz_date_and_no_date,ERROR,botocore.errorfactory.BucketAlreadyExists,An error occurred (BucketAlreadyExists) when calling the CreateBucket operation: A vault with the provided name already exists
s3tests_boto3.functional.test_headers,test_object_create_bad_authorization_none,ERROR,botocore.errorfactory.BucketAlreadyExists,An error occurred (BucketAlreadyExists) when calling the CreateBucket operation: A vault with the provided name already exists
s3tests_boto3.functional.test_headers,test_bucket_create_contentlength_none,PASSED,
s3tests_boto3.functional.test_headers,test_object_acl_create_contentlength_none,PASSED,
s3tests_boto3.functional.test_headers,test_bucket_put_bad_canned_acl,ERROR,botocore.errorfactory.BucketAlreadyOwnedByYou,An error occurred (BucketAlreadyOwnedByYou) when calling the CreateBucket operation: Your previous request to create the named bucket succeeded and you already own it.
s3tests_boto3.functional.test_headers,test_bucket_create_bad_expect_mismatch,ERROR,botocore.exceptions.ClientError,An error occurred (417) when calling the CreateBucket operation: Expectation Failed
s3tests_boto3.functional.test_headers,test_bucket_create_bad_expect_empty,ERROR,botocore.exceptions.ClientError,An error occurred (417) when calling the CreateBucket operation: Expectation Failed
s3tests_boto3.functional.test_headers,test_bucket_create_bad_contentlength_empty,PASSED,
s3tests_boto3.functional.test_headers,test_bucket_create_bad_contentlength_negative,PASSED,
s3tests_boto3.functional.test_headers,test_bucket_create_bad_contentlength_none,ERROR,botocore.errorfactory.BucketAlreadyExists,An error occurred (BucketAlreadyExists) when calling the CreateBucket operation: A vault with the provided name already exists
s3tests_boto3.functional.test_headers,test_bucket_create_bad_authorization_empty,FAILED,exceptions.AssertionError,409 != 403
s3tests_boto3.functional.test_headers,test_bucket_create_bad_authorization_none,FAILED,exceptions.AssertionError,ClientError not raised
s3tests_boto3.functional.test_headers,test_object_create_bad_md5_invalid_garbage_aws2,ERROR,botocore.errorfactory.BucketAlreadyOwnedByYou,An error occurred (BucketAlreadyOwnedByYou) when calling the CreateBucket operation: Your previous request to create the named bucket succeeded and you already own it.
s3tests_boto3.functional.test_headers,test_object_create_bad_contentlength_mismatch_below_aws2,ERROR,botocore.errorfactory.BucketAlreadyExists,An error occurred (BucketAlreadyExists) when calling the CreateBucket operation: A vault with the provided name already exists
s3tests_boto3.functional.test_headers,test_object_create_bad_authorization_incorrect_aws2,FAILED,exceptions.AssertionError,ClientError not raised
s3tests_boto3.functional.test_headers,test_object_create_bad_authorization_invalid_aws2,FAILED,exceptions.AssertionError,404 != 400
s3tests_boto3.functional.test_headers,test_object_create_bad_ua_empty_aws2,ERROR,botocore.errorfactory.BucketAlreadyOwnedByYou,An error occurred (BucketAlreadyOwnedByYou) when calling the CreateBucket operation: Your previous request to create the named bucket succeeded and you already own it.
s3tests_boto3.functional.test_headers,test_object_create_bad_ua_none_aws2,PASSED,
s3tests_boto3.functional.test_headers,test_object_create_bad_date_invalid_aws2,ERROR,botocore.errorfactory.BucketAlreadyExists,An error occurred (BucketAlreadyExists) when calling the CreateBucket operation: A vault with the provided name already exists
s3tests_boto3.functional.test_headers,test_object_create_bad_date_empty_aws2,ERROR,botocore.errorfactory.BucketAlreadyExists,An error occurred (BucketAlreadyExists) when calling the CreateBucket operation: A vault with the provided name already exists
s3tests_boto3.functional.test_headers,test_object_create_bad_date_none_aws2,ERROR,botocore.errorfactory.BucketAlreadyOwnedByYou,An error occurred (BucketAlreadyOwnedByYou) when calling the CreateBucket operation: Your previous request to create the named bucket succeeded and you already own it.
s3tests_boto3.functional.test_headers,test_object_create_bad_date_before_today_aws2,PASSED,
s3tests_boto3.functional.test_headers,test_object_create_bad_date_before_epoch_aws2,PASSED,
s3tests_boto3.functional.test_headers,test_object_create_bad_date_after_end_aws2,ERROR,botocore.errorfactory.BucketAlreadyExists,An error occurred (BucketAlreadyExists) when calling the CreateBucket operation: A vault with the provided name already exists
s3tests_boto3.functional.test_headers,test_bucket_create_bad_authorization_invalid_aws2,FAILED,exceptions.AssertionError,409 != 400
s3tests_boto3.functional.test_headers,test_bucket_create_bad_ua_empty_aws2,ERROR,botocore.errorfactory.BucketAlreadyExists,An error occurred (BucketAlreadyExists) when calling the CreateBucket operation: A vault with the provided name already exists
s3tests_boto3.functional.test_headers,test_bucket_create_bad_ua_none_aws2,ERROR,botocore.errorfactory.BucketAlreadyExists,An error occurred (BucketAlreadyExists) when calling the CreateBucket operation: A vault with the provided name already exists
s3tests_boto3.functional.test_headers,test_bucket_create_bad_date_invalid_aws2,PASSED,
s3tests_boto3.functional.test_headers,test_bucket_create_bad_date_empty_aws2,FAILED,exceptions.AssertionError,409 != 403
s3tests_boto3.functional.test_headers,test_bucket_create_bad_date_none_aws2,FAILED,exceptions.AssertionError,ClientError not raised
s3tests_boto3.functional.test_headers,test_bucket_create_bad_date_before_today_aws2,PASSED,
s3tests_boto3.functional.test_headers,test_bucket_create_bad_date_after_today_aws2,PASSED,
s3tests_boto3.functional.test_headers,test_bucket_create_bad_date_before_epoch_aws2,PASSED,
s3tests_boto3.functional.test_s3,test_bucket_list_empty,ERROR,botocore.errorfactory.BucketAlreadyExists,An error occurred (BucketAlreadyExists) when calling the CreateBucket operation: A vault with the provided name already exists
s3tests_boto3.functional.test_s3,test_bucket_list_distinct,ERROR,botocore.errorfactory.BucketAlreadyExists,An error occurred (BucketAlreadyExists) when calling the CreateBucket operation: A vault with the provided name already exists
s3tests_boto3.functional.test_s3,test_bucket_list_many,ERROR,botocore.errorfactory.BucketAlreadyExists,An error occurred (BucketAlreadyExists) when calling the CreateBucket operation: A vault with the provided name already exists
s3tests_boto3.functional.test_s3,test_bucket_listv2_many,ERROR,botocore.errorfactory.BucketAlreadyExists,An error occurred (BucketAlreadyExists) when calling the CreateBucket operation: A vault with the provided name already exists
s3tests_boto3.functional.test_s3,test_basic_key_count,ERROR,botocore.errorfactory.BucketAlreadyExists,An error occurred (BucketAlreadyExists) when calling the CreateBucket operation: A vault with the provided name already exists
s3tests_boto3.functional.test_s3,test_bucket_list_delimiter_basic,ERROR,botocore.errorfactory.BucketAlreadyOwnedByYou,An error occurred (BucketAlreadyOwnedByYou) when calling the CreateBucket operation: Your previous request to create the named bucket succeeded and you already own it.
s3tests_boto3.functional.test_s3,test_bucket_listv2_delimiter_basic,ERROR,botocore.errorfactory.NoSuchBucket,An error occurred (NoSuchBucket) when calling the ListObjectsV2 operation: The specified bucket does not exist.
s3tests_boto3.functional.test_s3,test_bucket_list_delimiter_prefix,ERROR,botocore.errorfactory.BucketAlreadyExists,An error occurred (BucketAlreadyExists) when calling the CreateBucket operation: A vault with the provided name already exists
s3tests_boto3.functional.test_s3,test_bucket_listv2_delimiter_prefix,ERROR,botocore.errorfactory.BucketAlreadyExists,An error occurred (BucketAlreadyExists) when calling the CreateBucket operation: A vault with the provided name already exists
s3tests_boto3.functional.test_s3,test_bucket_listv2_delimiter_prefix_ends_with_delimiter,ERROR,botocore.errorfactory.BucketAlreadyExists,An error occurred (BucketAlreadyExists) when calling the CreateBucket operation: A vault with the provided name already exists
s3tests_boto3.functional.test_s3,test_bucket_list_delimiter_prefix_ends_with_delimiter,ERROR,botocore.errorfactory.BucketAlreadyExists,An error occurred (BucketAlreadyExists) when calling the CreateBucket operation: A vault with the provided name already exists
s3tests_boto3.functional.test_s3,test_bucket_list_delimiter_alt,ERROR,botocore.errorfactory.NoSuchBucket,An error occurred (NoSuchBucket) when calling the ListObjects operation: The specified bucket does not exist.
s3tests_boto3.functional.test_s3,test_bucket_listv2_delimiter_alt,ERROR,botocore.errorfactory.BucketAlreadyExists,An error occurred (BucketAlreadyExists) when calling the CreateBucket operation: A vault with the provided name already exists
s3tests_boto3.functional.test_s3,test_bucket_list_delimiter_prefix_underscore,ERROR,botocore.errorfactory.BucketAlreadyExists,An error occurred (BucketAlreadyExists) when calling the CreateBucket operation: A vault with the provided name already exists
s3tests_boto3.functional.test_s3,test_bucket_listv2_delimiter_prefix_underscore,ERROR,botocore.errorfactory.BucketAlreadyOwnedByYou,An error occurred (BucketAlreadyOwnedByYou) when calling the CreateBucket operation: Your previous request to create the named bucket succeeded and you already own it.
s3tests_boto3.functional.test_s3,test_bucket_list_delimiter_percentage,ERROR,botocore.errorfactory.BucketAlreadyExists,An error occurred (BucketAlreadyExists) when calling the CreateBucket operation: A vault with the provided name already exists
s3tests_boto3.functional.test_s3,test_bucket_listv2_delimiter_percentage,PASSED,
s3tests_boto3.functional.test_s3,test_bucket_list_delimiter_whitespace,ERROR,botocore.errorfactory.BucketAlreadyOwnedByYou,An error occurred (BucketAlreadyOwnedByYou) when calling the CreateBucket operation: Your previous request to create the named bucket succeeded and you already own it.
s3tests_boto3.functional.test_s3,test_bucket_listv2_delimiter_whitespace,ERROR,botocore.errorfactory.BucketAlreadyOwnedByYou,An error occurred (BucketAlreadyOwnedByYou) when calling the CreateBucket operation: Your previous request to create the named bucket succeeded and you already own it.
s3tests_boto3.functional.test_s3,test_bucket_list_delimiter_dot,ERROR,botocore.errorfactory.BucketAlreadyExists,An error occurred (BucketAlreadyExists) when calling the CreateBucket operation: A vault with the provided name already exists
s3tests_boto3.functional.test_s3,test_bucket_listv2_delimiter_dot,ERROR,botocore.errorfactory.BucketAlreadyOwnedByYou,An error occurred (BucketAlreadyOwnedByYou) when calling the CreateBucket operation: Your previous request to create the named bucket succeeded and you already own it.
s3tests_boto3.functional.test_s3,test_bucket_list_delimiter_unreadable,ERROR,botocore.errorfactory.NoSuchBucket,An error occurred (NoSuchBucket) when calling the ListObjects operation: The specified bucket does not exist.
s3tests_boto3.functional.test_s3,test_bucket_listv2_delimiter_unreadable,ERROR,botocore.errorfactory.BucketAlreadyExists,An error occurred (BucketAlreadyExists) when calling the CreateBucket operation: A vault with the provided name already exists
s3tests_boto3.functional.test_s3,test_bucket_list_delimiter_empty,FAILED,exceptions.AssertionError,True != False
s3tests_boto3.functional.test_s3,test_bucket_listv2_delimiter_empty,ERROR,botocore.errorfactory.BucketAlreadyExists,An error occurred (BucketAlreadyExists) when calling the CreateBucket operation: A vault with the provided name already exists
s3tests_boto3.functional.test_s3,test_bucket_list_delimiter_none,ERROR,botocore.errorfactory.BucketAlreadyExists,An error occurred (BucketAlreadyExists) when calling the CreateBucket operation: A vault with the provided name already exists
s3tests_boto3.functional.test_s3,test_bucket_listv2_delimiter_none,ERROR,botocore.errorfactory.BucketAlreadyExists,An error occurred (BucketAlreadyExists) when calling the CreateBucket operation: A vault with the provided name already exists
s3tests_boto3.functional.test_s3,test_bucket_listv2_fetchowner_notempty,ERROR,botocore.errorfactory.NoSuchBucket,An error occurred (NoSuchBucket) when calling the ListObjectsV2 operation: The specified bucket does not exist.
s3tests_boto3.functional.test_s3,test_bucket_listv2_fetchowner_defaultempty,ERROR,botocore.errorfactory.BucketAlreadyOwnedByYou,An error occurred (BucketAlreadyOwnedByYou) when calling the CreateBucket operation: Your previous request to create the named bucket succeeded and you already own it.
s3tests_boto3.functional.test_s3,test_bucket_listv2_fetchowner_empty,ERROR,botocore.errorfactory.BucketAlreadyExists,An error occurred (BucketAlreadyExists) when calling the CreateBucket operation: A vault with the provided name already exists
s3tests_boto3.functional.test_s3,test_bucket_list_delimiter_not_exist,ERROR,botocore.errorfactory.BucketAlreadyExists,An error occurred (BucketAlreadyExists) when calling the CreateBucket operation: A vault with the provided name already exists
s3tests_boto3.functional.test_s3,test_bucket_listv2_delimiter_not_exist,PASSED,
s3tests_boto3.functional.test_s3,test_bucket_list_prefix_basic,ERROR,botocore.errorfactory.BucketAlreadyExists,An error occurred (BucketAlreadyExists) when calling the CreateBucket operation: A vault with the provided name already exists
s3tests_boto3.functional.test_s3,test_bucket_listv2_prefix_basic,ERROR,botocore.errorfactory.BucketAlreadyExists,An error occurred (BucketAlreadyExists) when calling the CreateBucket operation: A vault with the provided name already exists
s3tests_boto3.functional.test_s3,test_bucket_list_prefix_alt,ERROR,botocore.errorfactory.NoSuchBucket,An error occurred (NoSuchBucket) when calling the ListObjects operation: The specified bucket does not exist.
s3tests_boto3.functional.test_s3,test_bucket_listv2_prefix_alt,ERROR,botocore.errorfactory.BucketAlreadyExists,An error occurred (BucketAlreadyExists) when calling the CreateBucket operation: A vault with the provided name already exists
s3tests_boto3.functional.test_s3,test_bucket_list_prefix_empty,ERROR,botocore.errorfactory.BucketAlreadyOwnedByYou,An error occurred (BucketAlreadyOwnedByYou) when calling the CreateBucket operation: Your previous request to create the named bucket succeeded and you already own it.
s3tests_boto3.functional.test_s3,test_bucket_listv2_prefix_empty,ERROR,botocore.errorfactory.NoSuchBucket,An error occurred (NoSuchBucket) when calling the ListObjectsV2 operation: The specified bucket does not exist.
s3tests_boto3.functional.test_s3,test_bucket_list_prefix_none,ERROR,botocore.errorfactory.BucketAlreadyExists,An error occurred (BucketAlreadyExists) when calling the CreateBucket operation: A vault with the provided name already exists
s3tests_boto3.functional.test_s3,test_bucket_listv2_prefix_none,ERROR,botocore.errorfactory.NoSuchBucket,An error occurred (NoSuchBucket) when calling the ListObjectsV2 operation: The specified bucket does not exist.
s3tests_boto3.functional.test_s3,test_bucket_list_prefix_not_exist,ERROR,botocore.errorfactory.BucketAlreadyExists,An error occurred (BucketAlreadyExists) when calling the CreateBucket operation: A vault with the provided name already exists
s3tests_boto3.functional.test_s3,test_bucket_listv2_prefix_not_exist,ERROR,botocore.errorfactory.BucketAlreadyExists,An error occurred (BucketAlreadyExists) when calling the CreateBucket operation: A vault with the provided name already exists
s3tests_boto3.functional.test_s3,test_bucket_list_prefix_unreadable,ERROR,botocore.errorfactory.BucketAlreadyExists,An error occurred (BucketAlreadyExists) when calling the CreateBucket operation: A vault with the provided name already exists
s3tests_boto3.functional.test_s3,test_bucket_listv2_prefix_unreadable,ERROR,botocore.errorfactory.BucketAlreadyExists,An error occurred (BucketAlreadyExists) when calling the CreateBucket operation: A vault with the provided name already exists
s3tests_boto3.functional.test_s3,test_bucket_list_prefix_delimiter_basic,ERROR,botocore.errorfactory.BucketAlreadyExists,An error occurred (BucketAlreadyExists) when calling the CreateBucket operation: A vault with the provided name already exists
s3tests_boto3.functional.test_s3,test_bucket_listv2_prefix_delimiter_basic,ERROR,botocore.errorfactory.BucketAlreadyExists,An error occurred (BucketAlreadyExists) when calling the CreateBucket operation: A vault with the provided name already exists
s3tests_boto3.functional.test_s3,test_bucket_list_prefix_delimiter_alt,ERROR,botocore.errorfactory.NoSuchBucket,An error occurred (NoSuchBucket) when calling the ListObjects operation: The specified bucket does not exist.
s3tests_boto3.functional.test_s3,test_bucket_listv2_prefix_delimiter_alt,ERROR,botocore.errorfactory.BucketAlreadyExists,An error occurred (BucketAlreadyExists) when calling the CreateBucket operation: A vault with the provided name already exists
s3tests_boto3.functional.test_s3,test_bucket_list_prefix_delimiter_prefix_not_exist,PASSED,
s3tests_boto3.functional.test_s3,test_bucket_listv2_prefix_delimiter_prefix_not_exist,ERROR,botocore.errorfactory.NoSuchBucket,An error occurred (NoSuchBucket) when calling the ListObjectsV2 operation: The specified bucket does not exist.
s3tests_boto3.functional.test_s3,test_bucket_list_prefix_delimiter_delimiter_not_exist,ERROR,botocore.errorfactory.BucketAlreadyOwnedByYou,An error occurred (BucketAlreadyOwnedByYou) when calling the CreateBucket operation: Your previous request to create the named bucket succeeded and you already own it.
s3tests_boto3.functional.test_s3,test_bucket_listv2_prefix_delimiter_delimiter_not_exist,ERROR,botocore.errorfactory.BucketAlreadyExists,An error occurred (BucketAlreadyExists) when calling the CreateBucket operation: A vault with the provided name already exists
s3tests_boto3.functional.test_s3,test_bucket_list_prefix_delimiter_prefix_delimiter_not_exist,ERROR,botocore.errorfactory.BucketAlreadyExists,An error occurred (BucketAlreadyExists) when calling the CreateBucket operation: A vault with the provided name already exists
s3tests_boto3.functional.test_s3,test_bucket_listv2_prefix_delimiter_prefix_delimiter_not_exist,ERROR,botocore.errorfactory.BucketAlreadyExists,An error occurred (BucketAlreadyExists) when calling the CreateBucket operation: A vault with the provided name already exists
s3tests_boto3.functional.test_s3,test_bucket_list_maxkeys_one,ERROR,botocore.errorfactory.BucketAlreadyOwnedByYou,An error occurred (BucketAlreadyOwnedByYou) when calling the CreateBucket operation: Your previous request to create the named bucket succeeded and you already own it.
s3tests_boto3.functional.test_s3,test_bucket_listv2_maxkeys_one,ERROR,botocore.errorfactory.BucketAlreadyExists,An error occurred (BucketAlreadyExists) when calling the CreateBucket operation: A vault with the provided name already exists
s3tests_boto3.functional.test_s3,test_bucket_list_maxkeys_zero,ERROR,botocore.errorfactory.BucketAlreadyExists,An error occurred (BucketAlreadyExists) when calling the CreateBucket operation: A vault with the provided name already exists
s3tests_boto3.functional.test_s3,test_bucket_listv2_maxkeys_zero,ERROR,botocore.errorfactory.BucketAlreadyExists,An error occurred (BucketAlreadyExists) when calling the CreateBucket operation: A vault with the provided name already exists
s3tests_boto3.functional.test_s3,test_bucket_list_maxkeys_none,ERROR,botocore.errorfactory.BucketAlreadyExists,An error occurred (BucketAlreadyExists) when calling the CreateBucket operation: A vault with the provided name already exists
s3tests_boto3.functional.test_s3,test_bucket_listv2_maxkeys_none,ERROR,botocore.errorfactory.BucketAlreadyExists,An error occurred (BucketAlreadyExists) when calling the CreateBucket operation: A vault with the provided name already exists
s3tests_boto3.functional.test_s3,test_bucket_list_unordered,ERROR,botocore.errorfactory.BucketAlreadyExists,An error occurred (BucketAlreadyExists) when calling the CreateBucket operation: A vault with the provided name already exists
s3tests_boto3.functional.test_s3,test_bucket_listv2_unordered,ERROR,botocore.errorfactory.BucketAlreadyExists,An error occurred (BucketAlreadyExists) when calling the CreateBucket operation: A vault with the provided name already exists
s3tests_boto3.functional.test_s3,test_bucket_list_maxkeys_invalid,ERROR,botocore.errorfactory.BucketAlreadyOwnedByYou,An error occurred (BucketAlreadyOwnedByYou) when calling the CreateBucket operation: Your previous request to create the named bucket succeeded and you already own it.
s3tests_boto3.functional.test_s3,test_bucket_list_marker_none,ERROR,botocore.errorfactory.NoSuchBucket,An error occurred (NoSuchBucket) when calling the ListObjects operation: The specified bucket does not exist.
s3tests_boto3.functional.test_s3,test_bucket_listv2_continuationtoken_none,ERROR,botocore.errorfactory.NoSuchBucket,An error occurred (NoSuchBucket) when calling the ListObjectsV2 operation: The specified bucket does not exist.
s3tests_boto3.functional.test_s3,test_bucket_list_marker_empty,ERROR,botocore.errorfactory.NoSuchBucket,An error occurred (NoSuchBucket) when calling the ListObjects operation: The specified bucket does not exist.
s3tests_boto3.functional.test_s3,test_bucket_listv2_continuationtoken_empty,ERROR,botocore.errorfactory.BucketAlreadyExists,An error occurred (BucketAlreadyExists) when calling the CreateBucket operation: A vault with the provided name already exists
s3tests_boto3.functional.test_s3,test_bucket_list_marker_unreadable,ERROR,botocore.errorfactory.BucketAlreadyExists,An error occurred (BucketAlreadyExists) when calling the CreateBucket operation: A vault with the provided name already exists
s3tests_boto3.functional.test_s3,test_bucket_listv2_startafter_unreadable,ERROR,botocore.errorfactory.NoSuchBucket,An error occurred (NoSuchBucket) when calling the ListObjectsV2 operation: The specified bucket does not exist.
s3tests_boto3.functional.test_s3,test_bucket_list_marker_not_in_list,ERROR,botocore.errorfactory.BucketAlreadyExists,An error occurred (BucketAlreadyExists) when calling the CreateBucket operation: A vault with the provided name already exists
s3tests_boto3.functional.test_s3,test_bucket_listv2_startafter_not_in_list,ERROR,botocore.errorfactory.BucketAlreadyExists,An error occurred (BucketAlreadyExists) when calling the CreateBucket operation: A vault with the provided name already exists
s3tests_boto3.functional.test_s3,test_bucket_list_marker_after_list,ERROR,botocore.errorfactory.BucketAlreadyOwnedByYou,An error occurred (BucketAlreadyOwnedByYou) when calling the CreateBucket operation: Your previous request to create the named bucket succeeded and you already own it.
s3tests_boto3.functional.test_s3,test_bucket_listv2_startafter_after_list,ERROR,botocore.errorfactory.BucketAlreadyExists,An error occurred (BucketAlreadyExists) when calling the CreateBucket operation: A vault with the provided name already exists
s3tests_boto3.functional.test_s3,test_bucket_list_return_data,ERROR,botocore.exceptions.ClientError,An error occurred (404) when calling the HeadObject operation: Not Found
s3tests_boto3.functional.test_s3,test_bucket_list_objects_anonymous,ERROR,botocore.errorfactory.BucketAlreadyExists,An error occurred (BucketAlreadyExists) when calling the CreateBucket operation: A vault with the provided name already exists
s3tests_boto3.functional.test_s3,test_bucket_listv2_objects_anonymous,ERROR,botocore.errorfactory.BucketAlreadyExists,An error occurred (BucketAlreadyExists) when calling the CreateBucket operation: A vault with the provided name already exists
s3tests_boto3.functional.test_s3,test_bucket_list_objects_anonymous_fail,ERROR,botocore.errorfactory.BucketAlreadyExists,An error occurred (BucketAlreadyExists) when calling the CreateBucket operation: A vault with the provided name already exists
s3tests_boto3.functional.test_s3,test_bucket_listv2_objects_anonymous_fail,FAILED,exceptions.AssertionError,404 != 403
s3tests_boto3.functional.test_s3,test_bucket_notexist,PASSED,
s3tests_boto3.functional.test_s3,test_bucketv2_notexist,PASSED,
s3tests_boto3.functional.test_s3,test_bucket_delete_notexist,PASSED,
s3tests_boto3.functional.test_s3,test_bucket_delete_nonempty,ERROR,botocore.errorfactory.BucketAlreadyExists,An error occurred (BucketAlreadyExists) when calling the CreateBucket operation: A vault with the provided name already exists
s3tests_boto3.functional.test_s3,test_bucket_concurrent_set_canned_acl,ERROR,botocore.errorfactory.BucketAlreadyExists,An error occurred (BucketAlreadyExists) when calling the CreateBucket operation: A vault with the provided name already exists
s3tests_boto3.functional.test_s3,test_object_write_to_nonexist_bucket,FAILED,exceptions.AssertionError,'NoSuchKey' != 'NoSuchBucket'
s3tests_boto3.functional.test_s3,test_bucket_create_delete,ERROR,botocore.errorfactory.NoSuchBucket,An error occurred (NoSuchBucket) when calling the DeleteBucket operation: The specified bucket does not exist.
s3tests_boto3.functional.test_s3,test_object_read_notexist,ERROR,botocore.errorfactory.BucketAlreadyExists,An error occurred (BucketAlreadyExists) when calling the CreateBucket operation: A vault with the provided name already exists
s3tests_boto3.functional.test_s3,test_object_requestid_matches_header_on_error,ERROR,botocore.errorfactory.BucketAlreadyExists,An error occurred (BucketAlreadyExists) when calling the CreateBucket operation: A vault with the provided name already exists
s3tests_boto3.functional.test_s3,test_multi_object_delete,ERROR,botocore.errorfactory.BucketAlreadyExists,An error occurred (BucketAlreadyExists) when calling the CreateBucket operation: A vault with the provided name already exists
s3tests_boto3.functional.test_s3,test_multi_objectv2_delete,ERROR,botocore.errorfactory.BucketAlreadyExists,An error occurred (BucketAlreadyExists) when calling the CreateBucket operation: A vault with the provided name already exists
s3tests_boto3.functional.test_s3,test_object_head_zero_bytes,ERROR,botocore.errorfactory.BucketAlreadyOwnedByYou,An error occurred (BucketAlreadyOwnedByYou) when calling the CreateBucket operation: Your previous request to create the named bucket succeeded and you already own it.
s3tests_boto3.functional.test_s3,test_object_write_check_etag,ERROR,botocore.errorfactory.BucketAlreadyExists,An error occurred (BucketAlreadyExists) when calling the CreateBucket operation: A vault with the provided name already exists
s3tests_boto3.functional.test_s3,test_object_write_cache_control,ERROR,botocore.errorfactory.NoSuchKey,An error occurred (NoSuchKey) when calling the PutObject operation: The specified key does not exist.
s3tests_boto3.functional.test_s3,test_object_write_expires,ERROR,botocore.errorfactory.BucketAlreadyExists,An error occurred (BucketAlreadyExists) when calling the CreateBucket operation: A vault with the provided name already exists
s3tests_boto3.functional.test_s3,test_object_write_read_update_read_delete,PASSED,
s3tests_boto3.functional.test_s3,test_object_set_get_metadata_none_to_good,ERROR,botocore.errorfactory.NoSuchKey,An error occurred (NoSuchKey) when calling the PutObject operation: The specified key does not exist.
s3tests_boto3.functional.test_s3,test_object_set_get_metadata_none_to_empty,ERROR,botocore.errorfactory.BucketAlreadyOwnedByYou,An error occurred (BucketAlreadyOwnedByYou) when calling the CreateBucket operation: Your previous request to create the named bucket succeeded and you already own it.
s3tests_boto3.functional.test_s3,test_object_set_get_metadata_overwrite_to_empty,ERROR,botocore.errorfactory.BucketAlreadyOwnedByYou,An error occurred (BucketAlreadyOwnedByYou) when calling the CreateBucket operation: Your previous request to create the named bucket succeeded and you already own it.
s3tests_boto3.functional.test_s3,test_object_set_get_unicode_metadata,ERROR,botocore.exceptions.ClientError,An error occurred (SignatureDoesNotMatch) when calling the PutObject operation: The request signature we calculated does not match the signature you provided. Check your AWS Secret Access Key and signing method. For more information| see REST Authentication and SOAP Authentication for details.
s3tests_boto3.functional.test_s3,test_object_set_get_non_utf8_metadata,ERROR,botocore.exceptions.ClientError,An error occurred (400) when calling the PutObject operation: Bad Request
s3tests_boto3.functional.test_s3,test_object_set_get_metadata_empty_to_unreadable_prefix,ERROR,botocore.exceptions.ClientError,An error occurred (400) when calling the PutObject operation: Bad Request
s3tests_boto3.functional.test_s3,test_object_set_get_metadata_empty_to_unreadable_suffix,ERROR,botocore.errorfactory.BucketAlreadyExists,An error occurred (BucketAlreadyExists) when calling the CreateBucket operation: A vault with the provided name already exists
s3tests_boto3.functional.test_s3,test_object_set_get_metadata_empty_to_unreadable_infix,ERROR,botocore.exceptions.ClientError,An error occurred (400) when calling the PutObject operation: Bad Request
s3tests_boto3.functional.test_s3,test_object_set_get_metadata_overwrite_to_unreadable_prefix,ERROR,botocore.errorfactory.BucketAlreadyExists,An error occurred (BucketAlreadyExists) when calling the CreateBucket operation: A vault with the provided name already exists
s3tests_boto3.functional.test_s3,test_object_set_get_metadata_overwrite_to_unreadable_suffix,ERROR,botocore.errorfactory.BucketAlreadyExists,An error occurred (BucketAlreadyExists) when calling the CreateBucket operation: A vault with the provided name already exists
s3tests_boto3.functional.test_s3,test_object_set_get_metadata_overwrite_to_unreadable_infix,ERROR,botocore.exceptions.ClientError,An error occurred (400) when calling the PutObject operation: Bad Request
s3tests_boto3.functional.test_s3,test_object_metadata_replaced_on_put,ERROR,botocore.errorfactory.BucketAlreadyOwnedByYou,An error occurred (BucketAlreadyOwnedByYou) when calling the CreateBucket operation: Your previous request to create the named bucket succeeded and you already own it.
s3tests_boto3.functional.test_s3,test_object_write_file,ERROR,botocore.errorfactory.BucketAlreadyExists,An error occurred (BucketAlreadyExists) when calling the CreateBucket operation: A vault with the provided name already exists
s3tests_boto3.functional.test_s3,test_post_object_anonymous_request,ERROR,botocore.errorfactory.BucketAlreadyExists,An error occurred (BucketAlreadyExists) when calling the CreateBucket operation: A vault with the provided name already exists
s3tests_boto3.functional.test_s3,test_post_object_authenticated_request,ERROR,botocore.errorfactory.BucketAlreadyExists,An error occurred (BucketAlreadyExists) when calling the CreateBucket operation: A vault with the provided name already exists
s3tests_boto3.functional.test_s3,test_post_object_authenticated_no_content_type,ERROR,botocore.errorfactory.BucketAlreadyOwnedByYou,An error occurred (BucketAlreadyOwnedByYou) when calling the CreateBucket operation: Your previous request to create the named bucket succeeded and you already own it.
s3tests_boto3.functional.test_s3,test_post_object_authenticated_request_bad_access_key,FAILED,exceptions.AssertionError,404 != 403
s3tests_boto3.functional.test_s3,test_post_object_set_success_code,ERROR,botocore.errorfactory.BucketAlreadyExists,An error occurred (BucketAlreadyExists) when calling the CreateBucket operation: A vault with the provided name already exists
s3tests_boto3.functional.test_s3,test_post_object_set_invalid_success_code,ERROR,botocore.errorfactory.BucketAlreadyExists,An error occurred (BucketAlreadyExists) when calling the CreateBucket operation: A vault with the provided name already exists
s3tests_boto3.functional.test_s3,test_post_object_upload_larger_than_chunk,ERROR,botocore.errorfactory.BucketAlreadyOwnedByYou,An error occurred (BucketAlreadyOwnedByYou) when calling the CreateBucket operation: Your previous request to create the named bucket succeeded and you already own it.
s3tests_boto3.functional.test_s3,test_post_object_set_key_from_filename,ERROR,botocore.errorfactory.BucketAlreadyExists,An error occurred (BucketAlreadyExists) when calling the CreateBucket operation: A vault with the provided name already exists
s3tests_boto3.functional.test_s3,test_post_object_ignored_header,ERROR,botocore.errorfactory.BucketAlreadyExists,An error occurred (BucketAlreadyExists) when calling the CreateBucket operation: A vault with the provided name already exists
s3tests_boto3.functional.test_s3,test_post_object_case_insensitive_condition_fields,ERROR,botocore.errorfactory.BucketAlreadyOwnedByYou,An error occurred (BucketAlreadyOwnedByYou) when calling the CreateBucket operation: Your previous request to create the named bucket succeeded and you already own it.
s3tests_boto3.functional.test_s3,test_post_object_escaped_field_values,ERROR,botocore.errorfactory.BucketAlreadyExists,An error occurred (BucketAlreadyExists) when calling the CreateBucket operation: A vault with the provided name already exists
s3tests_boto3.functional.test_s3,test_post_object_success_redirect_action,ERROR,botocore.errorfactory.BucketAlreadyExists,An error occurred (BucketAlreadyExists) when calling the CreateBucket operation: A vault with the provided name already exists
s3tests_boto3.functional.test_s3,test_post_object_invalid_signature,FAILED,exceptions.AssertionError,404 != 403
s3tests_boto3.functional.test_s3,test_post_object_invalid_access_key,PASSED,
s3tests_boto3.functional.test_s3,test_post_object_invalid_date_format,ERROR,botocore.errorfactory.BucketAlreadyOwnedByYou,An error occurred (BucketAlreadyOwnedByYou) when calling the CreateBucket operation: Your previous request to create the named bucket succeeded and you already own it.
s3tests_boto3.functional.test_s3,test_post_object_no_key_specified,ERROR,botocore.errorfactory.BucketAlreadyOwnedByYou,An error occurred (BucketAlreadyOwnedByYou) when calling the CreateBucket operation: Your previous request to create the named bucket succeeded and you already own it.
s3tests_boto3.functional.test_s3,test_post_object_missing_signature,ERROR,botocore.errorfactory.BucketAlreadyOwnedByYou,An error occurred (BucketAlreadyOwnedByYou) when calling the CreateBucket operation: Your previous request to create the named bucket succeeded and you already own it.
s3tests_boto3.functional.test_s3,test_post_object_missing_policy_condition,ERROR,botocore.errorfactory.BucketAlreadyExists,An error occurred (BucketAlreadyExists) when calling the CreateBucket operation: A vault with the provided name already exists
s3tests_boto3.functional.test_s3,test_post_object_user_specified_header,ERROR,botocore.errorfactory.BucketAlreadyExists,An error occurred (BucketAlreadyExists) when calling the CreateBucket operation: A vault with the provided name already exists
s3tests_boto3.functional.test_s3,test_post_object_request_missing_policy_specified_field,ERROR,botocore.errorfactory.BucketAlreadyExists,An error occurred (BucketAlreadyExists) when calling the CreateBucket operation: A vault with the provided name already exists
s3tests_boto3.functional.test_s3,test_post_object_condition_is_case_sensitive,ERROR,botocore.errorfactory.BucketAlreadyExists,An error occurred (BucketAlreadyExists) when calling the CreateBucket operation: A vault with the provided name already exists
s3tests_boto3.functional.test_s3,test_post_object_expires_is_case_sensitive,ERROR,botocore.errorfactory.BucketAlreadyExists,An error occurred (BucketAlreadyExists) when calling the CreateBucket operation: A vault with the provided name already exists
s3tests_boto3.functional.test_s3,test_post_object_expired_policy,ERROR,botocore.errorfactory.BucketAlreadyExists,An error occurred (BucketAlreadyExists) when calling the CreateBucket operation: A vault with the provided name already exists
s3tests_boto3.functional.test_s3,test_post_object_invalid_request_field_value,ERROR,botocore.errorfactory.BucketAlreadyOwnedByYou,An error occurred (BucketAlreadyOwnedByYou) when calling the CreateBucket operation: Your previous request to create the named bucket succeeded and you already own it.
s3tests_boto3.functional.test_s3,test_post_object_missing_expires_condition,PASSED,
s3tests_boto3.functional.test_s3,test_post_object_missing_conditions_list,ERROR,botocore.errorfactory.BucketAlreadyExists,An error occurred (BucketAlreadyExists) when calling the CreateBucket operation: A vault with the provided name already exists
s3tests_boto3.functional.test_s3,test_post_object_upload_size_limit_exceeded,ERROR,botocore.errorfactory.BucketAlreadyExists,An error occurred (BucketAlreadyExists) when calling the CreateBucket operation: A vault with the provided name already exists
s3tests_boto3.functional.test_s3,test_post_object_missing_content_length_argument,ERROR,botocore.errorfactory.BucketAlreadyExists,An error occurred (BucketAlreadyExists) when calling the CreateBucket operation: A vault with the provided name already exists
s3tests_boto3.functional.test_s3,test_post_object_invalid_content_length_argument,ERROR,botocore.errorfactory.BucketAlreadyExists,An error occurred (BucketAlreadyExists) when calling the CreateBucket operation: A vault with the provided name already exists
s3tests_boto3.functional.test_s3,test_post_object_upload_size_below_minimum,ERROR,botocore.errorfactory.BucketAlreadyOwnedByYou,An error occurred (BucketAlreadyOwnedByYou) when calling the CreateBucket operation: Your previous request to create the named bucket succeeded and you already own it.
s3tests_boto3.functional.test_s3,test_post_object_empty_conditions,FAILED,exceptions.AssertionError,404 != 400
s3tests_boto3.functional.test_s3,test_get_object_ifmatch_good,ERROR,botocore.errorfactory.BucketAlreadyExists,An error occurred (BucketAlreadyExists) when calling the CreateBucket operation: A vault with the provided name already exists
s3tests_boto3.functional.test_s3,test_get_object_ifmatch_failed,ERROR,botocore.errorfactory.BucketAlreadyExists,An error occurred (BucketAlreadyExists) when calling the CreateBucket operation: A vault with the provided name already exists
s3tests_boto3.functional.test_s3,test_get_object_ifnonematch_good,ERROR,botocore.errorfactory.NoSuchKey,An error occurred (NoSuchKey) when calling the PutObject operation: The specified key does not exist.
s3tests_boto3.functional.test_s3,test_get_object_ifnonematch_failed,ERROR,botocore.errorfactory.BucketAlreadyExists,An error occurred (BucketAlreadyExists) when calling the CreateBucket operation: A vault with the provided name already exists
s3tests_boto3.functional.test_s3,test_get_object_ifmodifiedsince_good,ERROR,botocore.errorfactory.NoSuchKey,An error occurred (NoSuchKey) when calling the PutObject operation: The specified key does not exist.
s3tests_boto3.functional.test_s3,test_get_object_ifmodifiedsince_failed,ERROR,botocore.errorfactory.BucketAlreadyExists,An error occurred (BucketAlreadyExists) when calling the CreateBucket operation: A vault with the provided name already exists
s3tests_boto3.functional.test_s3,test_get_object_ifunmodifiedsince_good,ERROR,botocore.errorfactory.BucketAlreadyExists,An error occurred (BucketAlreadyExists) when calling the CreateBucket operation: A vault with the provided name already exists
s3tests_boto3.functional.test_s3,test_get_object_ifunmodifiedsince_failed,ERROR,botocore.errorfactory.BucketAlreadyExists,An error occurred (BucketAlreadyExists) when calling the CreateBucket operation: A vault with the provided name already exists
s3tests_boto3.functional.test_s3,test_put_object_ifmatch_good,ERROR,botocore.errorfactory.BucketAlreadyExists,An error occurred (BucketAlreadyExists) when calling the CreateBucket operation: A vault with the provided name already exists
s3tests_boto3.functional.test_s3,test_put_object_ifmatch_failed,ERROR,botocore.errorfactory.BucketAlreadyExists,An error occurred (BucketAlreadyExists) when calling the CreateBucket operation: A vault with the provided name already exists
s3tests_boto3.functional.test_s3,test_put_object_ifmatch_overwrite_existed_good,ERROR,botocore.errorfactory.BucketAlreadyOwnedByYou,An error occurred (BucketAlreadyOwnedByYou) when calling the CreateBucket operation: Your previous request to create the named bucket succeeded and you already own it.
s3tests_boto3.functional.test_s3,test_put_object_ifmatch_nonexisted_failed,ERROR,botocore.errorfactory.BucketAlreadyOwnedByYou,An error occurred (BucketAlreadyOwnedByYou) when calling the CreateBucket operation: Your previous request to create the named bucket succeeded and you already own it.
s3tests_boto3.functional.test_s3,test_put_object_ifnonmatch_good,ERROR,botocore.errorfactory.BucketAlreadyExists,An error occurred (BucketAlreadyExists) when calling the CreateBucket operation: A vault with the provided name already exists
s3tests_boto3.functional.test_s3,test_put_object_ifnonmatch_failed,ERROR,botocore.errorfactory.BucketAlreadyExists,An error occurred (BucketAlreadyExists) when calling the CreateBucket operation: A vault with the provided name already exists
s3tests_boto3.functional.test_s3,test_put_object_ifnonmatch_nonexisted_good,ERROR,botocore.errorfactory.BucketAlreadyExists,An error occurred (BucketAlreadyExists) when calling the CreateBucket operation: A vault with the provided name already exists
s3tests_boto3.functional.test_s3,test_put_object_ifnonmatch_overwrite_existed_failed,ERROR,botocore.errorfactory.BucketAlreadyExists,An error occurred (BucketAlreadyExists) when calling the CreateBucket operation: A vault with the provided name already exists
s3tests_boto3.functional.test_s3,test_object_raw_get,ERROR,botocore.errorfactory.BucketAlreadyExists,An error occurred (BucketAlreadyExists) when calling the CreateBucket operation: A vault with the provided name already exists
s3tests_boto3.functional.test_s3,test_object_raw_get_bucket_gone,ERROR,botocore.errorfactory.NoSuchKey,An error occurred (NoSuchKey) when calling the DeleteObject operation: The specified key does not exist.
s3tests_boto3.functional.test_s3,test_object_delete_key_bucket_gone,ERROR,botocore.errorfactory.BucketAlreadyExists,An error occurred (BucketAlreadyExists) when calling the CreateBucket operation: A vault with the provided name already exists
s3tests_boto3.functional.test_s3,test_object_raw_get_object_gone,ERROR,botocore.errorfactory.NoSuchKey,An error occurred (NoSuchKey) when calling the DeleteObject operation: The specified key does not exist.
s3tests_boto3.functional.test_s3,test_bucket_head,ERROR,botocore.errorfactory.BucketAlreadyExists,An error occurred (BucketAlreadyExists) when calling the CreateBucket operation: A vault with the provided name already exists
s3tests_boto3.functional.test_s3,test_bucket_head_extended,ERROR,botocore.exceptions.ClientError,An error occurred (404) when calling the HeadBucket operation: Not Found
s3tests_boto3.functional.test_s3,test_object_raw_get_bucket_acl,ERROR,botocore.errorfactory.BucketAlreadyExists,An error occurred (BucketAlreadyExists) when calling the CreateBucket operation: A vault with the provided name already exists
s3tests_boto3.functional.test_s3,test_object_raw_get_object_acl,ERROR,botocore.errorfactory.BucketAlreadyExists,An error occurred (BucketAlreadyExists) when calling the CreateBucket operation: A vault with the provided name already exists
s3tests_boto3.functional.test_s3,test_object_raw_authenticated,ERROR,botocore.errorfactory.BucketAlreadyExists,An error occurred (BucketAlreadyExists) when calling the CreateBucket operation: A vault with the provided name already exists
s3tests_boto3.functional.test_s3,test_object_raw_response_headers,ERROR,botocore.errorfactory.BucketAlreadyOwnedByYou,An error occurred (BucketAlreadyOwnedByYou) when calling the CreateBucket operation: Your previous request to create the named bucket succeeded and you already own it.
s3tests_boto3.functional.test_s3,test_object_raw_authenticated_bucket_acl,ERROR,botocore.errorfactory.BucketAlreadyExists,An error occurred (BucketAlreadyExists) when calling the CreateBucket operation: A vault with the provided name already exists
s3tests_boto3.functional.test_s3,test_object_raw_authenticated_object_acl,ERROR,botocore.errorfactory.NoSuchKey,An error occurred (NoSuchKey) when calling the GetObject operation: The specified key does not exist.
s3tests_boto3.functional.test_s3,test_object_raw_authenticated_bucket_gone,ERROR,botocore.errorfactory.BucketAlreadyExists,An error occurred (BucketAlreadyExists) when calling the CreateBucket operation: A vault with the provided name already exists
s3tests_boto3.functional.test_s3,test_object_raw_authenticated_object_gone,PASSED,
s3tests_boto3.functional.test_s3,test_object_raw_get_x_amz_expires_not_expired,FAILED,exceptions.AssertionError,404 != 200
s3tests_boto3.functional.test_s3,test_object_raw_get_x_amz_expires_out_range_zero,ERROR,botocore.errorfactory.BucketAlreadyExists,An error occurred (BucketAlreadyExists) when calling the CreateBucket operation: A vault with the provided name already exists
s3tests_boto3.functional.test_s3,test_object_raw_get_x_amz_expires_out_max_range,ERROR,botocore.errorfactory.BucketAlreadyExists,An error occurred (BucketAlreadyExists) when calling the CreateBucket operation: A vault with the provided name already exists
s3tests_boto3.functional.test_s3,test_object_raw_get_x_amz_expires_out_positive_range,ERROR,botocore.errorfactory.BucketAlreadyExists,An error occurred (BucketAlreadyExists) when calling the CreateBucket operation: A vault with the provided name already exists
s3tests_boto3.functional.test_s3,test_object_anon_put,ERROR,botocore.errorfactory.BucketAlreadyOwnedByYou,An error occurred (BucketAlreadyOwnedByYou) when calling the CreateBucket operation: Your previous request to create the named bucket succeeded and you already own it.
s3tests_boto3.functional.test_s3,test_object_anon_put_write_access,ERROR,botocore.errorfactory.BucketAlreadyExists,An error occurred (BucketAlreadyExists) when calling the CreateBucket operation: A vault with the provided name already exists
s3tests_boto3.functional.test_s3,test_object_put_authenticated,ERROR,botocore.errorfactory.BucketAlreadyExists,An error occurred (BucketAlreadyExists) when calling the CreateBucket operation: A vault with the provided name already exists
s3tests_boto3.functional.test_s3,test_object_raw_put_authenticated_expired,ERROR,botocore.errorfactory.BucketAlreadyExists,An error occurred (BucketAlreadyExists) when calling the CreateBucket operation: A vault with the provided name already exists
s3tests_boto3.functional.test_s3,test_bucket_create_naming_bad_starts_nonalpha,FAILED,exceptions.AssertionError,409 != 400
s3tests_boto3.functional.test_s3,test_bucket_create_naming_bad_short_empty,PASSED,
s3tests_boto3.functional.test_s3,test_bucket_create_naming_bad_short_one,FAILED,exceptions.AssertionError,409 != 400
s3tests_boto3.functional.test_s3,test_bucket_create_naming_bad_short_two,FAILED,exceptions.AssertionError,409 != 400
s3tests_boto3.functional.test_s3,test_bucket_create_naming_bad_long,PASSED,
s3tests_boto3.functional.test_s3,test_bucket_create_naming_good_long_250,PASSED,
s3tests_boto3.functional.test_s3,test_bucket_create_naming_good_long_251,ERROR,botocore.errorfactory.BucketAlreadyExists,An error occurred (BucketAlreadyExists) when calling the CreateBucket operation: A vault with the provided name already exists
s3tests_boto3.functional.test_s3,test_bucket_create_naming_good_long_252,PASSED,
s3tests_boto3.functional.test_s3,test_bucket_create_naming_good_long_253,ERROR,botocore.errorfactory.BucketAlreadyOwnedByYou,An error occurred (BucketAlreadyOwnedByYou) when calling the CreateBucket operation: Your previous request to create the named bucket succeeded and you already own it.
s3tests_boto3.functional.test_s3,test_bucket_create_naming_good_long_254,ERROR,botocore.errorfactory.BucketAlreadyExists,An error occurred (BucketAlreadyExists) when calling the CreateBucket operation: A vault with the provided name already exists
s3tests_boto3.functional.test_s3,test_bucket_create_naming_good_long_255,ERROR,botocore.errorfactory.BucketAlreadyExists,An error occurred (BucketAlreadyExists) when calling the CreateBucket operation: A vault with the provided name already exists
s3tests_boto3.functional.test_s3,test_bucket_list_long_name,PASSED,
s3tests_boto3.functional.test_s3,test_bucket_create_naming_bad_ip,FAILED,exceptions.AssertionError,409 != 400
s3tests_boto3.functional.test_s3,test_bucket_create_naming_bad_punctuation,PASSED,
s3tests_boto3.functional.test_s3,test_bucket_create_naming_dns_underscore,ERROR,botocore.errorfactory.BucketAlreadyExists,An error occurred (BucketAlreadyExists) when calling the CreateBucket operation: A vault with the provided name already exists
s3tests_boto3.functional.test_s3,test_bucket_create_naming_dns_long,ERROR,botocore.errorfactory.BucketAlreadyExists,An error occurred (BucketAlreadyExists) when calling the CreateBucket operation: A vault with the provided name already exists
s3tests_boto3.functional.test_s3,test_bucket_create_naming_dns_dash_at_end,ERROR,botocore.errorfactory.BucketAlreadyOwnedByYou,An error occurred (BucketAlreadyOwnedByYou) when calling the CreateBucket operation: Your previous request to create the named bucket succeeded and you already own it.
s3tests_boto3.functional.test_s3,test_bucket_create_naming_dns_dot_dot,ERROR,botocore.exceptions.ClientError,An error occurred (InvalidBucketName) when calling the CreateBucket operation: Please enter a valid name. Valid characters are alphanumeric| dash| underscore| or period. Leading character must be a letter| number| or underscore. The name cannot end with a period.
s3tests_boto3.functional.test_s3,test_bucket_create_naming_dns_dot_dash,ERROR,botocore.errorfactory.BucketAlreadyExists,An error occurred (BucketAlreadyExists) when calling the CreateBucket operation: A vault with the provided name already exists
s3tests_boto3.functional.test_s3,test_bucket_create_naming_dns_dash_dot,ERROR,botocore.errorfactory.BucketAlreadyExists,An error occurred (BucketAlreadyExists) when calling the CreateBucket operation: A vault with the provided name already exists
s3tests_boto3.functional.test_s3,test_bucket_create_exists,ERROR,exceptions.AttributeError,'BucketAlreadyOwnedByYou' object has no attribute 'status'
s3tests_boto3.functional.test_s3,test_bucket_get_location,ERROR,botocore.errorfactory.BucketAlreadyOwnedByYou,An error occurred (BucketAlreadyOwnedByYou) when calling the CreateBucket operation: Your previous request to create the named bucket succeeded and you already own it.
s3tests_boto3.functional.test_s3,test_bucket_create_exists_nonowner,ERROR,botocore.errorfactory.BucketAlreadyOwnedByYou,An error occurred (BucketAlreadyOwnedByYou) when calling the CreateBucket operation: Your previous request to create the named bucket succeeded and you already own it.
s3tests_boto3.functional.test_s3,test_bucket_acl_default,ERROR,botocore.errorfactory.BucketAlreadyExists,An error occurred (BucketAlreadyExists) when calling the CreateBucket operation: A vault with the provided name already exists
s3tests_boto3.functional.test_s3,test_bucket_acl_canned_during_create,ERROR,botocore.errorfactory.BucketAlreadyExists,An error occurred (BucketAlreadyExists) when calling the CreateBucket operation: A vault with the provided name already exists
s3tests_boto3.functional.test_s3,test_bucket_acl_canned,ERROR,botocore.errorfactory.BucketAlreadyOwnedByYou,An error occurred (BucketAlreadyOwnedByYou) when calling the CreateBucket operation: Your previous request to create the named bucket succeeded and you already own it.
s3tests_boto3.functional.test_s3,test_bucket_acl_canned_publicreadwrite,ERROR,botocore.errorfactory.BucketAlreadyExists,An error occurred (BucketAlreadyExists) when calling the CreateBucket operation: A vault with the provided name already exists
s3tests_boto3.functional.test_s3,test_bucket_acl_canned_authenticatedread,ERROR,botocore.exceptions.ClientError,An error occurred (InvalidArgument) when calling the CreateBucket operation: Authenticated users group not supported for vault resource
s3tests_boto3.functional.test_s3,test_object_acl_default,ERROR,botocore.errorfactory.BucketAlreadyExists,An error occurred (BucketAlreadyExists) when calling the CreateBucket operation: A vault with the provided name already exists
s3tests_boto3.functional.test_s3,test_object_acl_canned_during_create,ERROR,botocore.errorfactory.BucketAlreadyExists,An error occurred (BucketAlreadyExists) when calling the CreateBucket operation: A vault with the provided name already exists
s3tests_boto3.functional.test_s3,test_object_acl_canned,ERROR,botocore.errorfactory.BucketAlreadyExists,An error occurred (BucketAlreadyExists) when calling the CreateBucket operation: A vault with the provided name already exists
s3tests_boto3.functional.test_s3,test_object_acl_canned_publicreadwrite,ERROR,botocore.errorfactory.BucketAlreadyExists,An error occurred (BucketAlreadyExists) when calling the CreateBucket operation: A vault with the provided name already exists
s3tests_boto3.functional.test_s3,test_object_acl_canned_authenticatedread,ERROR,botocore.errorfactory.BucketAlreadyExists,An error occurred (BucketAlreadyExists) when calling the CreateBucket operation: A vault with the provided name already exists
s3tests_boto3.functional.test_s3,test_object_acl_canned_bucketownerread,ERROR,botocore.errorfactory.BucketAlreadyExists,An error occurred (BucketAlreadyExists) when calling the CreateBucket operation: A vault with the provided name already exists
s3tests_boto3.functional.test_s3,test_object_acl_canned_bucketownerfullcontrol,ERROR,botocore.errorfactory.BucketAlreadyExists,An error occurred (BucketAlreadyExists) when calling the CreateBucket operation: A vault with the provided name already exists
s3tests_boto3.functional.test_s3,test_object_acl_full_control_verify_owner,ERROR,botocore.errorfactory.BucketAlreadyExists,An error occurred (BucketAlreadyExists) when calling the CreateBucket operation: A vault with the provided name already exists
s3tests_boto3.functional.test_s3,test_object_acl_full_control_verify_attributes,ERROR,botocore.errorfactory.BucketAlreadyExists,An error occurred (BucketAlreadyExists) when calling the CreateBucket operation: A vault with the provided name already exists
s3tests_boto3.functional.test_s3,test_bucket_acl_canned_private_to_private,PASSED,
s3tests_boto3.functional.test_s3,test_object_acl,ERROR,botocore.errorfactory.BucketAlreadyOwnedByYou,An error occurred (BucketAlreadyOwnedByYou) when calling the CreateBucket operation: Your previous request to create the named bucket succeeded and you already own it.
s3tests_boto3.functional.test_s3,test_object_acl_write,ERROR,botocore.errorfactory.BucketAlreadyExists,An error occurred (BucketAlreadyExists) when calling the CreateBucket operation: A vault with the provided name already exists
s3tests_boto3.functional.test_s3,test_object_acl_writeacp,ERROR,botocore.errorfactory.BucketAlreadyExists,An error occurred (BucketAlreadyExists) when calling the CreateBucket operation: A vault with the provided name already exists
s3tests_boto3.functional.test_s3,test_object_acl_read,ERROR,botocore.errorfactory.BucketAlreadyOwnedByYou,An error occurred (BucketAlreadyOwnedByYou) when calling the CreateBucket operation: Your previous request to create the named bucket succeeded and you already own it.
s3tests_boto3.functional.test_s3,test_object_acl_readacp,ERROR,botocore.errorfactory.NoSuchKey,An error occurred (NoSuchKey) when calling the PutObject operation: The specified key does not exist.
s3tests_boto3.functional.test_s3,test_bucket_acl_grant_userid_fullcontrol,ERROR,botocore.errorfactory.BucketAlreadyExists,An error occurred (BucketAlreadyExists) when calling the CreateBucket operation: A vault with the provided name already exists
s3tests_boto3.functional.test_s3,test_bucket_acl_grant_userid_read,ERROR,botocore.errorfactory.NoSuchBucket,An error occurred (NoSuchBucket) when calling the GetBucketAcl operation: The specified bucket does not exist.
s3tests_boto3.functional.test_s3,test_bucket_acl_grant_userid_readacp,ERROR,botocore.errorfactory.BucketAlreadyExists,An error occurred (BucketAlreadyExists) when calling the CreateBucket operation: A vault with the provided name already exists
s3tests_boto3.functional.test_s3,test_bucket_acl_grant_userid_write,ERROR,botocore.errorfactory.BucketAlreadyExists,An error occurred (BucketAlreadyExists) when calling the CreateBucket operation: A vault with the provided name already exists
s3tests_boto3.functional.test_s3,test_bucket_acl_grant_userid_writeacp,ERROR,botocore.errorfactory.BucketAlreadyOwnedByYou,An error occurred (BucketAlreadyOwnedByYou) when calling the CreateBucket operation: Your previous request to create the named bucket succeeded and you already own it.
s3tests_boto3.functional.test_s3,test_bucket_acl_grant_nonexist_user,ERROR,botocore.errorfactory.NoSuchBucket,An error occurred (NoSuchBucket) when calling the GetBucketAcl operation: The specified bucket does not exist.
s3tests_boto3.functional.test_s3,test_bucket_acl_no_grants,ERROR,botocore.errorfactory.BucketAlreadyExists,An error occurred (BucketAlreadyExists) when calling the CreateBucket operation: A vault with the provided name already exists
s3tests_boto3.functional.test_s3,test_object_header_acl_grants,ERROR,botocore.errorfactory.BucketAlreadyExists,An error occurred (BucketAlreadyExists) when calling the CreateBucket operation: A vault with the provided name already exists
s3tests_boto3.functional.test_s3,test_bucket_header_acl_grants,FAILED,exceptions.AssertionError,2 != 5
s3tests_boto3.functional.test_s3,test_bucket_acl_grant_email,ERROR,botocore.errorfactory.BucketAlreadyOwnedByYou,An error occurred (BucketAlreadyOwnedByYou) when calling the CreateBucket operation: Your previous request to create the named bucket succeeded and you already own it.
s3tests_boto3.functional.test_s3,test_bucket_acl_grant_email_notexist,ERROR,botocore.errorfactory.BucketAlreadyExists,An error occurred (BucketAlreadyExists) when calling the CreateBucket operation: A vault with the provided name already exists
s3tests_boto3.functional.test_s3,test_bucket_acl_revoke_all,ERROR,botocore.errorfactory.BucketAlreadyExists,An error occurred (BucketAlreadyExists) when calling the CreateBucket operation: A vault with the provided name already exists
s3tests_boto3.functional.test_s3,test_logging_toggle,ERROR,botocore.errorfactory.BucketAlreadyExists,An error occurred (BucketAlreadyExists) when calling the CreateBucket operation: A vault with the provided name already exists
s3tests_boto3.functional.test_s3,test_access_bucket_private_object_private,ERROR,botocore.errorfactory.BucketAlreadyExists,An error occurred (BucketAlreadyExists) when calling the CreateBucket operation: A vault with the provided name already exists
s3tests_boto3.functional.test_s3,test_access_bucket_private_objectv2_private,ERROR,botocore.errorfactory.BucketAlreadyExists,An error occurred (BucketAlreadyExists) when calling the CreateBucket operation: A vault with the provided name already exists
s3tests_boto3.functional.test_s3,test_access_bucket_private_object_publicread,ERROR,botocore.errorfactory.BucketAlreadyExists,An error occurred (BucketAlreadyExists) when calling the CreateBucket operation: A vault with the provided name already exists
s3tests_boto3.functional.test_s3,test_access_bucket_private_objectv2_publicread,PASSED,
s3tests_boto3.functional.test_s3,test_access_bucket_private_object_publicreadwrite,ERROR,botocore.errorfactory.NoSuchBucket,An error occurred (NoSuchBucket) when calling the PutBucketAcl operation: The specified bucket does not exist.
s3tests_boto3.functional.test_s3,test_access_bucket_private_objectv2_publicreadwrite,ERROR,botocore.errorfactory.BucketAlreadyOwnedByYou,An error occurred (BucketAlreadyOwnedByYou) when calling the CreateBucket operation: Your previous request to create the named bucket succeeded and you already own it.
s3tests_boto3.functional.test_s3,test_access_bucket_publicread_object_private,ERROR,botocore.errorfactory.BucketAlreadyExists,An error occurred (BucketAlreadyExists) when calling the CreateBucket operation: A vault with the provided name already exists
s3tests_boto3.functional.test_s3,test_access_bucket_publicread_object_publicread,ERROR,botocore.errorfactory.BucketAlreadyOwnedByYou,An error occurred (BucketAlreadyOwnedByYou) when calling the CreateBucket operation: Your previous request to create the named bucket succeeded and you already own it.
s3tests_boto3.functional.test_s3,test_access_bucket_publicread_object_publicreadwrite,ERROR,botocore.errorfactory.BucketAlreadyOwnedByYou,An error occurred (BucketAlreadyOwnedByYou) when calling the CreateBucket operation: Your previous request to create the named bucket succeeded and you already own it.
s3tests_boto3.functional.test_s3,test_access_bucket_publicreadwrite_object_private,ERROR,botocore.errorfactory.BucketAlreadyOwnedByYou,An error occurred (BucketAlreadyOwnedByYou) when calling the CreateBucket operation: Your previous request to create the named bucket succeeded and you already own it.
s3tests_boto3.functional.test_s3,test_access_bucket_publicreadwrite_object_publicread,ERROR,botocore.errorfactory.BucketAlreadyExists,An error occurred (BucketAlreadyExists) when calling the CreateBucket operation: A vault with the provided name already exists
s3tests_boto3.functional.test_s3,test_access_bucket_publicreadwrite_object_publicreadwrite,ERROR,botocore.errorfactory.BucketAlreadyExists,An error occurred (BucketAlreadyExists) when calling the CreateBucket operation: A vault with the provided name already exists
s3tests_boto3.functional.test_s3,test_buckets_create_then_list,ERROR,botocore.errorfactory.BucketAlreadyExists,An error occurred (BucketAlreadyExists) when calling the CreateBucket operation: A vault with the provided name already exists
s3tests_boto3.functional.test_s3,test_list_buckets_anonymous,FAILED,exceptions.AssertionError,30 != 0
s3tests_boto3.functional.test_s3,test_list_buckets_invalid_auth,PASSED,
s3tests_boto3.functional.test_s3,test_list_buckets_bad_auth,PASSED,
s3tests_boto3.functional.test_s3,test_bucket_create_naming_good_starts_alpha,ERROR,botocore.errorfactory.BucketAlreadyExists,An error occurred (BucketAlreadyExists) when calling the CreateBucket operation: A vault with the provided name already exists
s3tests_boto3.functional.test_s3,test_bucket_create_naming_good_starts_digit,ERROR,botocore.errorfactory.BucketAlreadyExists,An error occurred (BucketAlreadyExists) when calling the CreateBucket operation: A vault with the provided name already exists
s3tests_boto3.functional.test_s3,test_bucket_create_naming_good_contains_period,ERROR,botocore.errorfactory.BucketAlreadyExists,An error occurred (BucketAlreadyExists) when calling the CreateBucket operation: A vault with the provided name already exists
s3tests_boto3.functional.test_s3,test_bucket_create_naming_good_contains_hyphen,ERROR,botocore.errorfactory.BucketAlreadyOwnedByYou,An error occurred (BucketAlreadyOwnedByYou) when calling the CreateBucket operation: Your previous request to create the named bucket succeeded and you already own it.
s3tests_boto3.functional.test_s3,test_bucket_recreate_not_overriding,ERROR,botocore.errorfactory.BucketAlreadyOwnedByYou,An error occurred (BucketAlreadyOwnedByYou) when calling the CreateBucket operation: Your previous request to create the named bucket succeeded and you already own it.
s3tests_boto3.functional.test_s3,test_bucket_create_special_key_names,ERROR,botocore.errorfactory.BucketAlreadyOwnedByYou,An error occurred (BucketAlreadyOwnedByYou) when calling the CreateBucket operation: Your previous request to create the named bucket succeeded and you already own it.
s3tests_boto3.functional.test_s3,test_bucket_list_special_prefix,ERROR,botocore.errorfactory.BucketAlreadyExists,An error occurred (BucketAlreadyExists) when calling the CreateBucket operation: A vault with the provided name already exists
s3tests_boto3.functional.test_s3,test_object_copy_zero_size,ERROR,botocore.errorfactory.BucketAlreadyOwnedByYou,An error occurred (BucketAlreadyOwnedByYou) when calling the CreateBucket operation: Your previous request to create the named bucket succeeded and you already own it.
s3tests_boto3.functional.test_s3,test_object_copy_same_bucket,ERROR,botocore.errorfactory.BucketAlreadyExists,An error occurred (BucketAlreadyExists) when calling the CreateBucket operation: A vault with the provided name already exists
s3tests_boto3.functional.test_s3,test_object_copy_verify_contenttype,ERROR,botocore.errorfactory.BucketAlreadyExists,An error occurred (BucketAlreadyExists) when calling the CreateBucket operation: A vault with the provided name already exists
s3tests_boto3.functional.test_s3,test_object_copy_to_itself,ERROR,botocore.errorfactory.BucketAlreadyExists,An error occurred (BucketAlreadyExists) when calling the CreateBucket operation: A vault with the provided name already exists
s3tests_boto3.functional.test_s3,test_object_copy_to_itself_with_metadata,ERROR,botocore.errorfactory.BucketAlreadyExists,An error occurred (BucketAlreadyExists) when calling the CreateBucket operation: A vault with the provided name already exists
s3tests_boto3.functional.test_s3,test_object_copy_diff_bucket,ERROR,botocore.errorfactory.BucketAlreadyExists,An error occurred (BucketAlreadyExists) when calling the CreateBucket operation: A vault with the provided name already exists
s3tests_boto3.functional.test_s3,test_object_copy_not_owned_bucket,ERROR,botocore.errorfactory.BucketAlreadyExists,An error occurred (BucketAlreadyExists) when calling the CreateBucket operation: A vault with the provided name already exists
s3tests_boto3.functional.test_s3,test_object_copy_not_owned_object_bucket,ERROR,botocore.errorfactory.BucketAlreadyExists,An error occurred (BucketAlreadyExists) when calling the CreateBucket operation: A vault with the provided name already exists
s3tests_boto3.functional.test_s3,test_object_copy_canned_acl,ERROR,botocore.errorfactory.BucketAlreadyOwnedByYou,An error occurred (BucketAlreadyOwnedByYou) when calling the CreateBucket operation: Your previous request to create the named bucket succeeded and you already own it.
s3tests_boto3.functional.test_s3,test_object_copy_retaining_metadata,ERROR,botocore.errorfactory.BucketAlreadyExists,An error occurred (BucketAlreadyExists) when calling the CreateBucket operation: A vault with the provided name already exists
s3tests_boto3.functional.test_s3,test_object_copy_replacing_metadata,ERROR,botocore.errorfactory.BucketAlreadyExists,An error occurred (BucketAlreadyExists) when calling the CreateBucket operation: A vault with the provided name already exists
s3tests_boto3.functional.test_s3,test_object_copy_bucket_not_found,ERROR,botocore.errorfactory.BucketAlreadyExists,An error occurred (BucketAlreadyExists) when calling the CreateBucket operation: A vault with the provided name already exists
s3tests_boto3.functional.test_s3,test_object_copy_key_not_found,PASSED,
s3tests_boto3.functional.test_s3,test_multipart_upload_empty,ERROR,botocore.errorfactory.BucketAlreadyExists,An error occurred (BucketAlreadyExists) when calling the CreateBucket operation: A vault with the provided name already exists
s3tests_boto3.functional.test_s3,test_multipart_upload_small,ERROR,botocore.errorfactory.BucketAlreadyOwnedByYou,An error occurred (BucketAlreadyOwnedByYou) when calling the CreateBucket operation: Your previous request to create the named bucket succeeded and you already own it.
s3tests_boto3.functional.test_s3,test_multipart_copy_small,ERROR,botocore.errorfactory.BucketAlreadyOwnedByYou,An error occurred (BucketAlreadyOwnedByYou) when calling the CreateBucket operation: Your previous request to create the named bucket succeeded and you already own it.
s3tests_boto3.functional.test_s3,test_multipart_copy_invalid_range,ERROR,botocore.errorfactory.BucketAlreadyExists,An error occurred (BucketAlreadyExists) when calling the CreateBucket operation: A vault with the provided name already exists
s3tests_boto3.functional.test_s3,test_multipart_copy_without_range,ERROR,botocore.errorfactory.BucketAlreadyExists,An error occurred (BucketAlreadyExists) when calling the CreateBucket operation: A vault with the provided name already exists
s3tests_boto3.functional.test_s3,test_multipart_copy_special_names,ERROR,botocore.errorfactory.BucketAlreadyExists,An error occurred (BucketAlreadyExists) when calling the CreateBucket operation: A vault with the provided name already exists
s3tests_boto3.functional.test_s3,test_multipart_upload,ERROR,botocore.errorfactory.NoSuchKey,An error occurred (NoSuchKey) when calling the CreateMultipartUpload operation: The specified key does not exist.
s3tests_boto3.functional.test_s3,test_multipart_upload_resend_part,ERROR,botocore.errorfactory.BucketAlreadyExists,An error occurred (BucketAlreadyExists) when calling the CreateBucket operation: A vault with the provided name already exists
s3tests_boto3.functional.test_s3,test_multipart_upload_multiple_sizes,ERROR,botocore.errorfactory.BucketAlreadyExists,An error occurred (BucketAlreadyExists) when calling the CreateBucket operation: A vault with the provided name already exists
s3tests_boto3.functional.test_s3,test_multipart_copy_multiple_sizes,ERROR,botocore.errorfactory.BucketAlreadyExists,An error occurred (BucketAlreadyExists) when calling the CreateBucket operation: A vault with the provided name already exists
s3tests_boto3.functional.test_s3,test_multipart_upload_size_too_small,ERROR,botocore.errorfactory.BucketAlreadyExists,An error occurred (BucketAlreadyExists) when calling the CreateBucket operation: A vault with the provided name already exists
s3tests_boto3.functional.test_s3,test_multipart_upload_contents,ERROR,botocore.errorfactory.BucketAlreadyOwnedByYou,An error occurred (BucketAlreadyOwnedByYou) when calling the CreateBucket operation: Your previous request to create the named bucket succeeded and you already own it.
s3tests_boto3.functional.test_s3,test_multipart_upload_overwrite_existing_object,ERROR,botocore.errorfactory.BucketAlreadyExists,An error occurred (BucketAlreadyExists) when calling the CreateBucket operation: A vault with the provided name already exists
s3tests_boto3.functional.test_s3,test_abort_multipart_upload,ERROR,botocore.errorfactory.BucketAlreadyExists,An error occurred (BucketAlreadyExists) when calling the CreateBucket operation: A vault with the provided name already exists
s3tests_boto3.functional.test_s3,test_abort_multipart_upload_not_found,ERROR,botocore.errorfactory.BucketAlreadyOwnedByYou,An error occurred (BucketAlreadyOwnedByYou) when calling the CreateBucket operation: Your previous request to create the named bucket succeeded and you already own it.
s3tests_boto3.functional.test_s3,test_list_multipart_upload,PASSED,
s3tests_boto3.functional.test_s3,test_multipart_upload_missing_part,ERROR,botocore.errorfactory.BucketAlreadyExists,An error occurred (BucketAlreadyExists) when calling the CreateBucket operation: A vault with the provided name already exists
s3tests_boto3.functional.test_s3,test_multipart_upload_incorrect_etag,ERROR,botocore.errorfactory.BucketAlreadyExists,An error occurred (BucketAlreadyExists) when calling the CreateBucket operation: A vault with the provided name already exists
s3tests_boto3.functional.test_s3,test_100_continue,ERROR,botocore.errorfactory.BucketAlreadyExists,An error occurred (BucketAlreadyExists) when calling the CreateBucket operation: A vault with the provided name already exists
s3tests_boto3.functional.test_s3,test_set_cors,ERROR,botocore.errorfactory.BucketAlreadyExists,An error occurred (BucketAlreadyExists) when calling the CreateBucket operation: A vault with the provided name already exists
s3tests_boto3.functional.test_s3,test_cors_origin_response,ERROR,botocore.errorfactory.BucketAlreadyOwnedByYou,An error occurred (BucketAlreadyOwnedByYou) when calling the CreateBucket operation: Your previous request to create the named bucket succeeded and you already own it.
s3tests_boto3.functional.test_s3,test_cors_origin_wildcard,ERROR,botocore.errorfactory.BucketAlreadyExists,An error occurred (BucketAlreadyExists) when calling the CreateBucket operation: A vault with the provided name already exists
s3tests_boto3.functional.test_s3,test_cors_header_option,ERROR,botocore.errorfactory.NoSuchBucket,An error occurred (NoSuchBucket) when calling the PutBucketCors operation: The specified bucket does not exist.
s3tests_boto3.functional.test_s3,test_set_tagging,ERROR,botocore.errorfactory.BucketAlreadyExists,An error occurred (BucketAlreadyExists) when calling the CreateBucket operation: A vault with the provided name already exists
s3tests_boto3.functional.test_s3,test_atomic_read_1mb,ERROR,botocore.errorfactory.BucketAlreadyOwnedByYou,An error occurred (BucketAlreadyOwnedByYou) when calling the CreateBucket operation: Your previous request to create the named bucket succeeded and you already own it.
s3tests_boto3.functional.test_s3,test_atomic_read_4mb,ERROR,botocore.errorfactory.NoSuchKey,An error occurred (NoSuchKey) when calling the PutObject operation: The specified key does not exist.
s3tests_boto3.functional.test_s3,test_atomic_read_8mb,ERROR,botocore.errorfactory.NoSuchKey,An error occurred (NoSuchKey) when calling the PutObject operation: The specified key does not exist.
s3tests_boto3.functional.test_s3,test_atomic_write_1mb,ERROR,botocore.errorfactory.BucketAlreadyExists,An error occurred (BucketAlreadyExists) when calling the CreateBucket operation: A vault with the provided name already exists
s3tests_boto3.functional.test_s3,test_atomic_write_4mb,ERROR,botocore.errorfactory.BucketAlreadyOwnedByYou,An error occurred (BucketAlreadyOwnedByYou) when calling the CreateBucket operation: Your previous request to create the named bucket succeeded and you already own it.
s3tests_boto3.functional.test_s3,test_atomic_write_8mb,ERROR,botocore.errorfactory.BucketAlreadyOwnedByYou,An error occurred (BucketAlreadyOwnedByYou) when calling the CreateBucket operation: Your previous request to create the named bucket succeeded and you already own it.
s3tests_boto3.functional.test_s3,test_atomic_dual_write_1mb,ERROR,botocore.errorfactory.BucketAlreadyExists,An error occurred (BucketAlreadyExists) when calling the CreateBucket operation: A vault with the provided name already exists
s3tests_boto3.functional.test_s3,test_atomic_dual_write_4mb,ERROR,botocore.errorfactory.BucketAlreadyExists,An error occurred (BucketAlreadyExists) when calling the CreateBucket operation: A vault with the provided name already exists
s3tests_boto3.functional.test_s3,test_atomic_dual_write_8mb,ERROR,botocore.errorfactory.BucketAlreadyExists,An error occurred (BucketAlreadyExists) when calling the CreateBucket operation: A vault with the provided name already exists
s3tests_boto3.functional.test_s3,test_atomic_conditional_write_1mb,ERROR,botocore.errorfactory.BucketAlreadyExists,An error occurred (BucketAlreadyExists) when calling the CreateBucket operation: A vault with the provided name already exists
s3tests_boto3.functional.test_s3,test_atomic_dual_conditional_write_1mb,ERROR,botocore.errorfactory.BucketAlreadyExists,An error occurred (BucketAlreadyExists) when calling the CreateBucket operation: A vault with the provided name already exists
s3tests_boto3.functional.test_s3,test_atomic_write_bucket_gone,ERROR,botocore.errorfactory.BucketAlreadyExists,An error occurred (BucketAlreadyExists) when calling the CreateBucket operation: A vault with the provided name already exists
s3tests_boto3.functional.test_s3,test_atomic_multipart_upload_write,ERROR,botocore.errorfactory.BucketAlreadyExists,An error occurred (BucketAlreadyExists) when calling the CreateBucket operation: A vault with the provided name already exists
s3tests_boto3.functional.test_s3,test_multipart_resend_first_finishes_last,ERROR,botocore.errorfactory.BucketAlreadyExists,An error occurred (BucketAlreadyExists) when calling the CreateBucket operation: A vault with the provided name already exists
s3tests_boto3.functional.test_s3,test_ranged_request_response_code,ERROR,botocore.errorfactory.NoSuchKey,An error occurred (NoSuchKey) when calling the PutObject operation: The specified key does not exist.
s3tests_boto3.functional.test_s3,test_ranged_big_request_response_code,ERROR,botocore.errorfactory.BucketAlreadyExists,An error occurred (BucketAlreadyExists) when calling the CreateBucket operation: A vault with the provided name already exists
s3tests_boto3.functional.test_s3,test_ranged_request_skip_leading_bytes_response_code,ERROR,botocore.errorfactory.NoSuchKey,An error occurred (NoSuchKey) when calling the PutObject operation: The specified key does not exist.
s3tests_boto3.functional.test_s3,test_ranged_request_return_trailing_bytes_response_code,ERROR,botocore.errorfactory.BucketAlreadyExists,An error occurred (BucketAlreadyExists) when calling the CreateBucket operation: A vault with the provided name already exists
s3tests_boto3.functional.test_s3,test_ranged_request_invalid_range,ERROR,botocore.errorfactory.BucketAlreadyExists,An error occurred (BucketAlreadyExists) when calling the CreateBucket operation: A vault with the provided name already exists
s3tests_boto3.functional.test_s3,test_ranged_request_empty_object,PASSED,
s3tests_boto3.functional.test_s3,test_lifecycle_set,ERROR,botocore.errorfactory.BucketAlreadyExists,An error occurred (BucketAlreadyExists) when calling the CreateBucket operation: A vault with the provided name already exists
s3tests_boto3.functional.test_s3,test_lifecycle_get,ERROR,botocore.errorfactory.BucketAlreadyExists,An error occurred (BucketAlreadyExists) when calling the CreateBucket operation: A vault with the provided name already exists
s3tests_boto3.functional.test_s3,test_lifecycle_get_no_id,ERROR,botocore.errorfactory.BucketAlreadyExists,An error occurred (BucketAlreadyExists) when calling the CreateBucket operation: A vault with the provided name already exists
s3tests_boto3.functional.test_s3,test_lifecycle_expiration,ERROR,botocore.errorfactory.BucketAlreadyExists,An error occurred (BucketAlreadyExists) when calling the CreateBucket operation: A vault with the provided name already exists
s3tests_boto3.functional.test_s3,test_lifecyclev2_expiration,ERROR,botocore.errorfactory.BucketAlreadyOwnedByYou,An error occurred (BucketAlreadyOwnedByYou) when calling the CreateBucket operation: Your previous request to create the named bucket succeeded and you already own it.
s3tests_boto3.functional.test_s3,test_lifecycle_id_too_long,ERROR,botocore.errorfactory.BucketAlreadyExists,An error occurred (BucketAlreadyExists) when calling the CreateBucket operation: A vault with the provided name already exists
s3tests_boto3.functional.test_s3,test_lifecycle_same_id,ERROR,botocore.errorfactory.BucketAlreadyExists,An error occurred (BucketAlreadyExists) when calling the CreateBucket operation: A vault with the provided name already exists
s3tests_boto3.functional.test_s3,test_lifecycle_invalid_status,ERROR,botocore.errorfactory.BucketAlreadyOwnedByYou,An error occurred (BucketAlreadyOwnedByYou) when calling the CreateBucket operation: Your previous request to create the named bucket succeeded and you already own it.
s3tests_boto3.functional.test_s3,test_lifecycle_set_date,ERROR,botocore.errorfactory.NoSuchBucket,An error occurred (NoSuchBucket) when calling the PutBucketLifecycleConfiguration operation: The specified bucket does not exist.
s3tests_boto3.functional.test_s3,test_lifecycle_set_invalid_date,ERROR,botocore.errorfactory.BucketAlreadyExists,An error occurred (BucketAlreadyExists) when calling the CreateBucket operation: A vault with the provided name already exists
s3tests_boto3.functional.test_s3,test_lifecycle_expiration_date,ERROR,botocore.errorfactory.BucketAlreadyExists,An error occurred (BucketAlreadyExists) when calling the CreateBucket operation: A vault with the provided name already exists
s3tests_boto3.functional.test_s3,test_lifecycle_expiration_days0,ERROR,botocore.exceptions.ClientError,An error occurred (MalformedXML) when calling the PutBucketLifecycleConfiguration operation: The XML you provided was not well-formed or did not validate against our published schema.
s3tests_boto3.functional.test_s3,test_lifecycle_set_noncurrent,ERROR,botocore.exceptions.ClientError,An error occurred (MalformedXML) when calling the PutBucketLifecycleConfiguration operation: The XML you provided was not well-formed or did not validate against our published schema.
s3tests_boto3.functional.test_s3,test_lifecycle_noncur_expiration,ERROR,botocore.errorfactory.BucketAlreadyExists,An error occurred (BucketAlreadyExists) when calling the CreateBucket operation: A vault with the provided name already exists
s3tests_boto3.functional.test_s3,test_lifecycle_set_deletemarker,ERROR,botocore.errorfactory.BucketAlreadyOwnedByYou,An error occurred (BucketAlreadyOwnedByYou) when calling the CreateBucket operation: Your previous request to create the named bucket succeeded and you already own it.
s3tests_boto3.functional.test_s3,test_lifecycle_set_filter,ERROR,botocore.errorfactory.BucketAlreadyOwnedByYou,An error occurred (BucketAlreadyOwnedByYou) when calling the CreateBucket operation: Your previous request to create the named bucket succeeded and you already own it.
s3tests_boto3.functional.test_s3,test_lifecycle_set_empty_filter,ERROR,botocore.errorfactory.NoSuchBucket,An error occurred (NoSuchBucket) when calling the PutBucketLifecycleConfiguration operation: The specified bucket does not exist.
s3tests_boto3.functional.test_s3,test_lifecycle_deletemarker_expiration,ERROR,exceptions.KeyError,'VersionId'
s3tests_boto3.functional.test_s3,test_lifecycle_set_multipart,ERROR,botocore.errorfactory.BucketAlreadyExists,An error occurred (BucketAlreadyExists) when calling the CreateBucket operation: A vault with the provided name already exists
s3tests_boto3.functional.test_s3,test_lifecycle_multipart_expiration,ERROR,botocore.errorfactory.BucketAlreadyExists,An error occurred (BucketAlreadyExists) when calling the CreateBucket operation: A vault with the provided name already exists
s3tests_boto3.functional.test_s3,test_encrypted_transfer_1b,ERROR,botocore.exceptions.ClientError,An error occurred (AccessDenied) when calling the PutObject operation: Access Denied - Server-Side Encryption with Customer-Provided Keys is not enabled for this vault.
s3tests_boto3.functional.test_s3,test_encrypted_transfer_1kb,ERROR,botocore.errorfactory.BucketAlreadyExists,An error occurred (BucketAlreadyExists) when calling the CreateBucket operation: A vault with the provided name already exists
s3tests_boto3.functional.test_s3,test_encrypted_transfer_1MB,ERROR,botocore.errorfactory.BucketAlreadyOwnedByYou,An error occurred (BucketAlreadyOwnedByYou) when calling the CreateBucket operation: Your previous request to create the named bucket succeeded and you already own it.
s3tests_boto3.functional.test_s3,test_encrypted_transfer_13b,ERROR,botocore.errorfactory.BucketAlreadyExists,An error occurred (BucketAlreadyExists) when calling the CreateBucket operation: A vault with the provided name already exists
s3tests_boto3.functional.test_s3,test_encryption_sse_c_method_head,ERROR,botocore.errorfactory.BucketAlreadyOwnedByYou,An error occurred (BucketAlreadyOwnedByYou) when calling the CreateBucket operation: Your previous request to create the named bucket succeeded and you already own it.
s3tests_boto3.functional.test_s3,test_encryption_sse_c_present,ERROR,botocore.errorfactory.BucketAlreadyExists,An error occurred (BucketAlreadyExists) when calling the CreateBucket operation: A vault with the provided name already exists
s3tests_boto3.functional.test_s3,test_encryption_sse_c_other_key,ERROR,botocore.errorfactory.BucketAlreadyExists,An error occurred (BucketAlreadyExists) when calling the CreateBucket operation: A vault with the provided name already exists
s3tests_boto3.functional.test_s3,test_encryption_sse_c_invalid_md5,ERROR,botocore.errorfactory.BucketAlreadyExists,An error occurred (BucketAlreadyExists) when calling the CreateBucket operation: A vault with the provided name already exists
s3tests_boto3.functional.test_s3,test_encryption_sse_c_no_md5,PASSED,
s3tests_boto3.functional.test_s3,test_encryption_sse_c_no_key,ERROR,botocore.errorfactory.BucketAlreadyExists,An error occurred (BucketAlreadyExists) when calling the CreateBucket operation: A vault with the provided name already exists
s3tests_boto3.functional.test_s3,test_encryption_key_no_sse_c,ERROR,botocore.errorfactory.BucketAlreadyExists,An error occurred (BucketAlreadyExists) when calling the CreateBucket operation: A vault with the provided name already exists
s3tests_boto3.functional.test_s3,test_encryption_sse_c_multipart_upload,ERROR,botocore.errorfactory.BucketAlreadyOwnedByYou,An error occurred (BucketAlreadyOwnedByYou) when calling the CreateBucket operation: Your previous request to create the named bucket succeeded and you already own it.
s3tests_boto3.functional.test_s3,test_encryption_sse_c_multipart_invalid_chunks_1,ERROR,botocore.errorfactory.BucketAlreadyOwnedByYou,An error occurred (BucketAlreadyOwnedByYou) when calling the CreateBucket operation: Your previous request to create the named bucket succeeded and you already own it.
s3tests_boto3.functional.test_s3,test_encryption_sse_c_multipart_invalid_chunks_2,ERROR,botocore.errorfactory.BucketAlreadyExists,An error occurred (BucketAlreadyExists) when calling the CreateBucket operation: A vault with the provided name already exists
s3tests_boto3.functional.test_s3,test_encryption_sse_c_multipart_bad_download,ERROR,botocore.errorfactory.BucketAlreadyOwnedByYou,An error occurred (BucketAlreadyOwnedByYou) when calling the CreateBucket operation: Your previous request to create the named bucket succeeded and you already own it.
s3tests_boto3.functional.test_s3,test_encryption_sse_c_post_object_authenticated_request,FAILED,exceptions.AssertionError,404 != 204
s3tests_boto3.functional.test_s3,test_sse_kms_transfer_1b,ERROR,botocore.errorfactory.BucketAlreadyExists,An error occurred (BucketAlreadyExists) when calling the CreateBucket operation: A vault with the provided name already exists
s3tests_boto3.functional.test_s3,test_sse_kms_transfer_1kb,ERROR,botocore.errorfactory.BucketAlreadyOwnedByYou,An error occurred (BucketAlreadyOwnedByYou) when calling the CreateBucket operation: Your previous request to create the named bucket succeeded and you already own it.
s3tests_boto3.functional.test_s3,test_sse_kms_transfer_1MB,ERROR,botocore.errorfactory.BucketAlreadyExists,An error occurred (BucketAlreadyExists) when calling the CreateBucket operation: A vault with the provided name already exists
s3tests_boto3.functional.test_s3,test_sse_kms_transfer_13b,ERROR,botocore.exceptions.ClientError,An error occurred (AccessDenied) when calling the PutObject operation: Access Denied - Server-Side Encryption with Customer-Provided Keys is not enabled for this vault.
s3tests_boto3.functional.test_s3,test_sse_kms_method_head,ERROR,botocore.errorfactory.NoSuchKey,An error occurred (NoSuchKey) when calling the PutObject operation: The specified key does not exist.
s3tests_boto3.functional.test_s3,test_sse_kms_present,ERROR,botocore.errorfactory.BucketAlreadyExists,An error occurred (BucketAlreadyExists) when calling the CreateBucket operation: A vault with the provided name already exists
s3tests_boto3.functional.test_s3,test_sse_kms_no_key,ERROR,botocore.errorfactory.BucketAlreadyExists,An error occurred (BucketAlreadyExists) when calling the CreateBucket operation: A vault with the provided name already exists
s3tests_boto3.functional.test_s3,test_sse_kms_not_declared,ERROR,botocore.errorfactory.BucketAlreadyExists,An error occurred (BucketAlreadyExists) when calling the CreateBucket operation: A vault with the provided name already exists
s3tests_boto3.functional.test_s3,test_sse_kms_multipart_upload,ERROR,botocore.errorfactory.BucketAlreadyOwnedByYou,An error occurred (BucketAlreadyOwnedByYou) when calling the CreateBucket operation: Your previous request to create the named bucket succeeded and you already own it.
s3tests_boto3.functional.test_s3,test_sse_kms_multipart_invalid_chunks_1,ERROR,botocore.errorfactory.BucketAlreadyExists,An error occurred (BucketAlreadyExists) when calling the CreateBucket operation: A vault with the provided name already exists
s3tests_boto3.functional.test_s3,test_sse_kms_multipart_invalid_chunks_2,ERROR,botocore.errorfactory.BucketAlreadyExists,An error occurred (BucketAlreadyExists) when calling the CreateBucket operation: A vault with the provided name already exists
s3tests_boto3.functional.test_s3,test_sse_kms_post_object_authenticated_request,ERROR,botocore.errorfactory.BucketAlreadyOwnedByYou,An error occurred (BucketAlreadyOwnedByYou) when calling the CreateBucket operation: Your previous request to create the named bucket succeeded and you already own it.
s3tests_boto3.functional.test_s3,test_sse_kms_barb_transfer_1b,ERROR,botocore.errorfactory.BucketAlreadyExists,An error occurred (BucketAlreadyExists) when calling the CreateBucket operation: A vault with the provided name already exists
s3tests_boto3.functional.test_s3,test_sse_kms_barb_transfer_1kb,ERROR,botocore.errorfactory.BucketAlreadyExists,An error occurred (BucketAlreadyExists) when calling the CreateBucket operation: A vault with the provided name already exists
s3tests_boto3.functional.test_s3,test_sse_kms_barb_transfer_1MB,ERROR,botocore.errorfactory.BucketAlreadyOwnedByYou,An error occurred (BucketAlreadyOwnedByYou) when calling the CreateBucket operation: Your previous request to create the named bucket succeeded and you already own it.
s3tests_boto3.functional.test_s3,test_sse_kms_barb_transfer_13b,ERROR,botocore.errorfactory.BucketAlreadyOwnedByYou,An error occurred (BucketAlreadyOwnedByYou) when calling the CreateBucket operation: Your previous request to create the named bucket succeeded and you already own it.
s3tests_boto3.functional.test_s3,test_sse_kms_read_declare,ERROR,botocore.errorfactory.BucketAlreadyExists,An error occurred (BucketAlreadyExists) when calling the CreateBucket operation: A vault with the provided name already exists
s3tests_boto3.functional.test_s3,test_bucket_policy,ERROR,botocore.errorfactory.BucketAlreadyExists,An error occurred (BucketAlreadyExists) when calling the CreateBucket operation: A vault with the provided name already exists
s3tests_boto3.functional.test_s3,test_bucketv2_policy,ERROR,botocore.errorfactory.BucketAlreadyExists,An error occurred (BucketAlreadyExists) when calling the CreateBucket operation: A vault with the provided name already exists
s3tests_boto3.functional.test_s3,test_bucket_policy_acl,ERROR,botocore.errorfactory.BucketAlreadyExists,An error occurred (BucketAlreadyExists) when calling the CreateBucket operation: A vault with the provided name already exists
s3tests_boto3.functional.test_s3,test_bucketv2_policy_acl,ERROR,botocore.errorfactory.BucketAlreadyExists,An error occurred (BucketAlreadyExists) when calling the CreateBucket operation: A vault with the provided name already exists
s3tests_boto3.functional.test_s3,test_bucket_policy_different_tenant,ERROR,botocore.errorfactory.BucketAlreadyExists,An error occurred (BucketAlreadyExists) when calling the CreateBucket operation: A vault with the provided name already exists
s3tests_boto3.functional.test_s3,test_bucketv2_policy_different_tenant,ERROR,botocore.errorfactory.BucketAlreadyExists,An error occurred (BucketAlreadyExists) when calling the CreateBucket operation: A vault with the provided name already exists
s3tests_boto3.functional.test_s3,test_bucket_policy_another_bucket,ERROR,botocore.errorfactory.BucketAlreadyExists,An error occurred (BucketAlreadyExists) when calling the CreateBucket operation: A vault with the provided name already exists
s3tests_boto3.functional.test_s3,test_bucketv2_policy_another_bucket,ERROR,botocore.errorfactory.BucketAlreadyOwnedByYou,An error occurred (BucketAlreadyOwnedByYou) when calling the CreateBucket operation: Your previous request to create the named bucket succeeded and you already own it.
s3tests_boto3.functional.test_s3,test_bucket_policy_set_condition_operator_end_with_IfExists,ERROR,botocore.errorfactory.BucketAlreadyExists,An error occurred (BucketAlreadyExists) when calling the CreateBucket operation: A vault with the provided name already exists
s3tests_boto3.functional.test_s3,test_get_obj_tagging,ERROR,botocore.errorfactory.NoSuchKey,An error occurred (NoSuchKey) when calling the PutObject operation: The specified key does not exist.
s3tests_boto3.functional.test_s3,test_get_obj_head_tagging,ERROR,botocore.errorfactory.NoSuchKey,An error occurred (NoSuchKey) when calling the PutObject operation: The specified key does not exist.
s3tests_boto3.functional.test_s3,test_put_max_tags,ERROR,botocore.errorfactory.BucketAlreadyExists,An error occurred (BucketAlreadyExists) when calling the CreateBucket operation: A vault with the provided name already exists
s3tests_boto3.functional.test_s3,test_put_excess_tags,ERROR,botocore.errorfactory.BucketAlreadyExists,An error occurred (BucketAlreadyExists) when calling the CreateBucket operation: A vault with the provided name already exists
s3tests_boto3.functional.test_s3,test_put_max_kvsize_tags,ERROR,botocore.errorfactory.BucketAlreadyExists,An error occurred (BucketAlreadyExists) when calling the CreateBucket operation: A vault with the provided name already exists
s3tests_boto3.functional.test_s3,test_put_excess_key_tags,ERROR,botocore.errorfactory.BucketAlreadyOwnedByYou,An error occurred (BucketAlreadyOwnedByYou) when calling the CreateBucket operation: Your previous request to create the named bucket succeeded and you already own it.
s3tests_boto3.functional.test_s3,test_put_excess_val_tags,ERROR,botocore.errorfactory.BucketAlreadyExists,An error occurred (BucketAlreadyExists) when calling the CreateBucket operation: A vault with the provided name already exists
s3tests_boto3.functional.test_s3,test_put_modify_tags,ERROR,botocore.errorfactory.NoSuchKey,An error occurred (NoSuchKey) when calling the PutObject operation: The specified key does not exist.
s3tests_boto3.functional.test_s3,test_put_delete_tags,ERROR,botocore.errorfactory.BucketAlreadyExists,An error occurred (BucketAlreadyExists) when calling the CreateBucket operation: A vault with the provided name already exists
s3tests_boto3.functional.test_s3,test_post_object_tags_anonymous_request,ERROR,botocore.errorfactory.BucketAlreadyExists,An error occurred (BucketAlreadyExists) when calling the CreateBucket operation: A vault with the provided name already exists
s3tests_boto3.functional.test_s3,test_post_object_tags_authenticated_request,ERROR,botocore.errorfactory.BucketAlreadyOwnedByYou,An error occurred (BucketAlreadyOwnedByYou) when calling the CreateBucket operation: Your previous request to create the named bucket succeeded and you already own it.
s3tests_boto3.functional.test_s3,test_put_obj_with_tags,ERROR,botocore.errorfactory.BucketAlreadyOwnedByYou,An error occurred (BucketAlreadyOwnedByYou) when calling the CreateBucket operation: Your previous request to create the named bucket succeeded and you already own it.
s3tests_boto3.functional.test_s3,test_get_tags_acl_public,ERROR,botocore.errorfactory.BucketAlreadyExists,An error occurred (BucketAlreadyExists) when calling the CreateBucket operation: A vault with the provided name already exists
s3tests_boto3.functional.test_s3,test_put_tags_acl_public,ERROR,botocore.errorfactory.BucketAlreadyExists,An error occurred (BucketAlreadyExists) when calling the CreateBucket operation: A vault with the provided name already exists
s3tests_boto3.functional.test_s3,test_delete_tags_obj_public,ERROR,botocore.errorfactory.BucketAlreadyOwnedByYou,An error occurred (BucketAlreadyOwnedByYou) when calling the CreateBucket operation: Your previous request to create the named bucket succeeded and you already own it.
s3tests_boto3.functional.test_s3,test_bucket_policy_get_obj_existing_tag,ERROR,botocore.errorfactory.BucketAlreadyExists,An error occurred (BucketAlreadyExists) when calling the CreateBucket operation: A vault with the provided name already exists
s3tests_boto3.functional.test_s3,test_bucket_policy_get_obj_tagging_existing_tag,ERROR,botocore.errorfactory.BucketAlreadyOwnedByYou,An error occurred (BucketAlreadyOwnedByYou) when calling the CreateBucket operation: Your previous request to create the named bucket succeeded and you already own it.
s3tests_boto3.functional.test_s3,test_bucket_policy_put_obj_tagging_existing_tag,ERROR,botocore.errorfactory.BucketAlreadyOwnedByYou,An error occurred (BucketAlreadyOwnedByYou) when calling the CreateBucket operation: Your previous request to create the named bucket succeeded and you already own it.
s3tests_boto3.functional.test_s3,test_bucket_policy_put_obj_copy_source,ERROR,botocore.errorfactory.BucketAlreadyExists,An error occurred (BucketAlreadyExists) when calling the CreateBucket operation: A vault with the provided name already exists
s3tests_boto3.functional.test_s3,test_bucket_policy_put_obj_copy_source_meta,ERROR,botocore.errorfactory.BucketAlreadyOwnedByYou,An error occurred (BucketAlreadyOwnedByYou) when calling the CreateBucket operation: Your previous request to create the named bucket succeeded and you already own it.
s3tests_boto3.functional.test_s3,test_bucket_policy_put_obj_acl,ERROR,botocore.errorfactory.BucketAlreadyExists,An error occurred (BucketAlreadyExists) when calling the CreateBucket operation: A vault with the provided name already exists
s3tests_boto3.functional.test_s3,test_bucket_policy_put_obj_grant,ERROR,botocore.errorfactory.BucketAlreadyExists,An error occurred (BucketAlreadyExists) when calling the CreateBucket operation: A vault with the provided name already exists
s3tests_boto3.functional.test_s3,test_bucket_policy_put_obj_enc,ERROR,botocore.errorfactory.BucketAlreadyOwnedByYou,An error occurred (BucketAlreadyOwnedByYou) when calling the CreateBucket operation: Your previous request to create the named bucket succeeded and you already own it.
s3tests_boto3.functional.test_s3,test_bucket_policy_put_obj_request_obj_tag,ERROR,botocore.exceptions.ClientError,An error occurred (UnsupportedOperation) when calling the PutBucketPolicy operation: The operation requested is not supported
s3tests_boto3.functional.test_s3,test_bucket_policy_get_obj_acl_existing_tag,ERROR,botocore.errorfactory.BucketAlreadyExists,An error occurred (BucketAlreadyExists) when calling the CreateBucket operation: A vault with the provided name already exists
s3tests_boto3.functional.test_s3,test_object_lock_put_obj_lock,ERROR,botocore.errorfactory.BucketAlreadyOwnedByYou,An error occurred (BucketAlreadyOwnedByYou) when calling the CreateBucket operation: Your previous request to create the named bucket succeeded and you already own it.
s3tests_boto3.functional.test_s3,test_object_lock_put_obj_lock_invalid_bucket,ERROR,botocore.errorfactory.BucketAlreadyExists,An error occurred (BucketAlreadyExists) when calling the CreateBucket operation: A vault with the provided name already exists
s3tests_boto3.functional.test_s3,test_object_lock_put_obj_lock_with_days_and_years,ERROR,botocore.errorfactory.BucketAlreadyOwnedByYou,An error occurred (BucketAlreadyOwnedByYou) when calling the CreateBucket operation: Your previous request to create the named bucket succeeded and you already own it.
s3tests_boto3.functional.test_s3,test_object_lock_put_obj_lock_invalid_days,ERROR,botocore.errorfactory.BucketAlreadyExists,An error occurred (BucketAlreadyExists) when calling the CreateBucket operation: A vault with the provided name already exists
s3tests_boto3.functional.test_s3,test_object_lock_put_obj_lock_invalid_years,ERROR,botocore.errorfactory.BucketAlreadyOwnedByYou,An error occurred (BucketAlreadyOwnedByYou) when calling the CreateBucket operation: Your previous request to create the named bucket succeeded and you already own it.
s3tests_boto3.functional.test_s3,test_object_lock_put_obj_lock_invalid_status,ERROR,botocore.errorfactory.BucketAlreadyExists,An error occurred (BucketAlreadyExists) when calling the CreateBucket operation: A vault with the provided name already exists
s3tests_boto3.functional.test_s3,test_object_lock_suspend_versioning,ERROR,botocore.errorfactory.BucketAlreadyExists,An error occurred (BucketAlreadyExists) when calling the CreateBucket operation: A vault with the provided name already exists
s3tests_boto3.functional.test_s3,test_object_lock_get_obj_lock,ERROR,botocore.errorfactory.BucketAlreadyExists,An error occurred (BucketAlreadyExists) when calling the CreateBucket operation: A vault with the provided name already exists
s3tests_boto3.functional.test_s3,test_object_lock_get_obj_lock_invalid_bucket,ERROR,botocore.errorfactory.BucketAlreadyExists,An error occurred (BucketAlreadyExists) when calling the CreateBucket operation: A vault with the provided name already exists
s3tests_boto3.functional.test_s3,test_object_lock_put_obj_retention,ERROR,botocore.errorfactory.BucketAlreadyOwnedByYou,An error occurred (BucketAlreadyOwnedByYou) when calling the CreateBucket operation: Your previous request to create the named bucket succeeded and you already own it.
s3tests_boto3.functional.test_s3,test_object_lock_put_obj_retention_invalid_bucket,ERROR,botocore.errorfactory.BucketAlreadyOwnedByYou,An error occurred (BucketAlreadyOwnedByYou) when calling the CreateBucket operation: Your previous request to create the named bucket succeeded and you already own it.
s3tests_boto3.functional.test_s3,test_object_lock_put_obj_retention_invalid_mode,ERROR,botocore.errorfactory.BucketAlreadyOwnedByYou,An error occurred (BucketAlreadyOwnedByYou) when calling the CreateBucket operation: Your previous request to create the named bucket succeeded and you already own it.
s3tests_boto3.functional.test_s3,test_object_lock_get_obj_retention,ERROR,botocore.errorfactory.BucketAlreadyExists,An error occurred (BucketAlreadyExists) when calling the CreateBucket operation: A vault with the provided name already exists
s3tests_boto3.functional.test_s3,test_object_lock_get_obj_retention_invalid_bucket,ERROR,botocore.errorfactory.BucketAlreadyExists,An error occurred (BucketAlreadyExists) when calling the CreateBucket operation: A vault with the provided name already exists
s3tests_boto3.functional.test_s3,test_object_lock_put_obj_retention_versionid,ERROR,botocore.errorfactory.BucketAlreadyExists,An error occurred (BucketAlreadyExists) when calling the CreateBucket operation: A vault with the provided name already exists
s3tests_boto3.functional.test_s3,test_object_lock_put_obj_retention_override_default_retention,ERROR,botocore.errorfactory.BucketAlreadyOwnedByYou,An error occurred (BucketAlreadyOwnedByYou) when calling the PutObjectLockConfiguration operation: Your previous request to create the named bucket succeeded and you already own it.
s3tests_boto3.functional.test_s3,test_object_lock_put_obj_retention_increase_period,ERROR,botocore.errorfactory.BucketAlreadyOwnedByYou,An error occurred (BucketAlreadyOwnedByYou) when calling the CreateBucket operation: Your previous request to create the named bucket succeeded and you already own it.
s3tests_boto3.functional.test_s3,test_object_lock_put_obj_retention_shorten_period,ERROR,botocore.errorfactory.BucketAlreadyExists,An error occurred (BucketAlreadyExists) when calling the CreateBucket operation: A vault with the provided name already exists
s3tests_boto3.functional.test_s3,test_object_lock_put_obj_retention_shorten_period_bypass,ERROR,exceptions.KeyError,'VersionId'
s3tests_boto3.functional.test_s3,test_object_lock_delete_object_with_retention,ERROR,botocore.errorfactory.BucketAlreadyExists,An error occurred (BucketAlreadyExists) when calling the CreateBucket operation: A vault with the provided name already exists
s3tests_boto3.functional.test_s3,test_object_lock_put_legal_hold,ERROR,botocore.errorfactory.BucketAlreadyExists,An error occurred (BucketAlreadyExists) when calling the CreateBucket operation: A vault with the provided name already exists
s3tests_boto3.functional.test_s3,test_object_lock_put_legal_hold_invalid_bucket,ERROR,botocore.errorfactory.BucketAlreadyExists,An error occurred (BucketAlreadyExists) when calling the CreateBucket operation: A vault with the provided name already exists
s3tests_boto3.functional.test_s3,test_object_lock_put_legal_hold_invalid_status,FAILED,exceptions.AssertionError,ClientError not raised
s3tests_boto3.functional.test_s3,test_object_lock_get_legal_hold,ERROR,botocore.errorfactory.BucketAlreadyExists,An error occurred (BucketAlreadyExists) when calling the CreateBucket operation: A vault with the provided name already exists
s3tests_boto3.functional.test_s3,test_object_lock_get_legal_hold_invalid_bucket,ERROR,botocore.errorfactory.BucketAlreadyExists,An error occurred (BucketAlreadyExists) when calling the CreateBucket operation: A vault with the provided name already exists
s3tests_boto3.functional.test_s3,test_object_lock_delete_object_with_legal_hold_on,ERROR,botocore.errorfactory.BucketAlreadyExists,An error occurred (BucketAlreadyExists) when calling the CreateBucket operation: A vault with the provided name already exists
s3tests_boto3.functional.test_s3,test_object_lock_delete_object_with_legal_hold_off,ERROR,botocore.errorfactory.BucketAlreadyExists,An error occurred (BucketAlreadyExists) when calling the CreateBucket operation: A vault with the provided name already exists
s3tests_boto3.functional.test_s3,test_object_lock_get_obj_metadata,ERROR,botocore.errorfactory.BucketAlreadyOwnedByYou,An error occurred (BucketAlreadyOwnedByYou) when calling the CreateBucket operation: Your previous request to create the named bucket succeeded and you already own it.
s3tests_boto3.functional.test_s3,test_object_lock_uploading_obj,ERROR,botocore.errorfactory.BucketAlreadyOwnedByYou,An error occurred (BucketAlreadyOwnedByYou) when calling the CreateBucket operation: Your previous request to create the named bucket succeeded and you already own it.
s3tests_boto3.functional.test_utils,test_generate,PASSED,
s3tests_boto3.fuzz.test.test_fuzzer,test_load_graph,PASSED,
s3tests_boto3.fuzz.test.test_fuzzer,test_descend_leaf_node,PASSED,
s3tests_boto3.fuzz.test.test_fuzzer,test_descend_node,PASSED,
s3tests_boto3.fuzz.test.test_fuzzer,test_descend_bad_node,PASSED,
s3tests_boto3.fuzz.test.test_fuzzer,test_descend_nonexistant_child,PASSED,
s3tests_boto3.fuzz.test.test_fuzzer,test_expand_random_printable,PASSED,
s3tests_boto3.fuzz.test.test_fuzzer,test_expand_random_binary,PASSED,
s3tests_boto3.fuzz.test.test_fuzzer,test_expand_random_printable_no_whitespace,PASSED,
s3tests_boto3.fuzz.test.test_fuzzer,test_expand_random_binary_no_whitespace,PASSED,
s3tests_boto3.fuzz.test.test_fuzzer,test_expand_random_no_args,PASSED,
s3tests_boto3.fuzz.test.test_fuzzer,test_expand_random_no_charset,PASSED,
s3tests_boto3.fuzz.test.test_fuzzer,test_expand_random_exact_length,PASSED,
s3tests_boto3.fuzz.test.test_fuzzer,test_expand_random_bad_charset,PASSED,
s3tests_boto3.fuzz.test.test_fuzzer,test_expand_random_missing_length,PASSED,
s3tests_boto3.fuzz.test.test_fuzzer,test_assemble_decision,PASSED,
s3tests_boto3.fuzz.test.test_fuzzer,test_expand_escape,PASSED,
s3tests_boto3.fuzz.test.test_fuzzer,test_expand_indirect,PASSED,
s3tests_boto3.fuzz.test.test_fuzzer,test_expand_indirect_double,PASSED,
s3tests_boto3.fuzz.test.test_fuzzer,test_expand_recursive,PASSED,
s3tests_boto3.fuzz.test.test_fuzzer,test_expand_recursive_mutual,PASSED,
s3tests_boto3.fuzz.test.test_fuzzer,test_expand_recursive_not_too_eager,PASSED,
s3tests_boto3.fuzz.test.test_fuzzer,test_make_choice_unweighted_with_space,PASSED,
s3tests_boto3.fuzz.test.test_fuzzer,test_weighted_choices,PASSED,
s3tests_boto3.fuzz.test.test_fuzzer,test_null_choices,PASSED,
s3tests_boto3.fuzz.test.test_fuzzer,test_weighted_null_choices,PASSED,
s3tests_boto3.fuzz.test.test_fuzzer,test_null_child,PASSED,
s3tests_boto3.fuzz.test.test_fuzzer,test_weighted_set,PASSED,
s3tests_boto3.fuzz.test.test_fuzzer,test_header_presence,PASSED,
s3tests_boto3.fuzz.test.test_fuzzer,test_duplicate_header,PASSED,
s3tests_boto3.fuzz.test.test_fuzzer,test_expand_headers,PASSED,
test_realistic.TestFileValidator,test_new_file_is_valid,PASSED,
test_realistic.TestFileValidator,test_new_file_is_valid_on_several_calls,PASSED,
test_realistic.TestFileValidator,test_new_file_is_valid_when_size_is_1,PASSED,
test_realistic.TestFiles,test_random_file_valid,PASSED,
Tests = 575 Errors = 427 Failures = 29 Skip = 0
